Workbook
Name ColumnTitle1: Invoice[[#Headers],[DESCRIPTION]]
Name ColumnTitle1: Invoice[[#Headers],[DESCRIPTION]]
Name ColumnTitleRegion1..B11.1: DN!$A$7
Name Company_Name: DN!$A$1
Name DDDD: '[1]MASTER LIST'!$1:$1048576
Name Masterlist: 'MASTER LIST'!$1:$1048576
Name NameList: 'MASTER LIST'!#REF!
Name NameList2: 'MASTER LIST'!#REF!
Name RowTitleRegion1..E5: DN!$H$2
Name s: '[2]MASTER LIST'!$1:$1048576
Name SSS: #REF!
Name Store_Name: Table118[STORES]
Name Store_Name: Table118[STORES]

Sheet CK_HF
A1: Nº | B1: DATE | C1: Month | D1: Week Num2 | E1: PO Number | F1: Document Number | G1: Delivered From/To | H1: BARCODE | I1: ITEM CODE | J1: ITEM NAME | K1: PACKING SIZE | L1: PURCHASE Uom | M1: QUANTITY | N1: Master List Prices | O1: INV Prices | P1: PRICE (USD) | Q1: TOTAL PRICE (USD) | R1: LAST TOTAL PRICE (USD) | S1: EXPRIED DATE | T1: ALERT | U1: REMARK | V1: Transaction Type | W1: Category | X1: Sub Category | Y1: H1
A2: 1 | B2: 45901 | C2: 9 | D2: Week 01 | G2: HEALTHY FOOD | H2: 0 | I2: REV-FOOD | J2: Revenue Food | K2: 0 | L2: 0 | M2: 1 | N2: 0 | O2: 173.38 | R2: 173.38 | V2: Sold | W2: FOOD | X2: FOOD | Y2: 0
A3: 2 | B3: 45901 | C3: 9 | D3: Week 01 | G3: HEALTHY FOOD | H3: 0 | I3: REV-NON ALCOHOL | J3: Revenue Non Alcohol | K3: 0 | L3: 0 | M3: 1 | N3: 0 | O3: 39.47 | R3: 39.47 | V3: Sold | W3: BEVERAGE NON-ALOCOHOL | X3: BEVERAGE NON-ALOCOHOL | Y3: 0
A4: 3 | B4: 45902 | C4: 9 | D4: Week 01 | G4: HEALTHY FOOD | H4: 0 | I4: REV-FOOD | J4: Revenue Food | K4: 0 | L4: 0 | M4: 1 | N4: 0 | O4: 114.75 | R4: 114.75 | V4: Sold | W4: FOOD | X4: FOOD | Y4: 0
A5: 4 | B5: 45902 | C5: 9 | D5: Week 01 | G5: HEALTHY FOOD | H5: 0 | I5: REV-NON ALCOHOL | J5: Revenue Non Alcohol | K5: 0 | L5: 0 | M5: 1 | N5: 0 | O5: 42 | R5: 42 | V5: Sold | W5: BEVERAGE NON-ALOCOHOL | X5: BEVERAGE NON-ALOCOHOL | Y5: 0
A6: 5 | B6: 45903 | C6: 9 | D6: Week 01 | G6: HEALTHY FOOD | H6: 0 | I6: REV-FOOD | J6: Revenue Food | K6: 0 | L6: 0 | M6: 1 | N6: 0 | O6: 74.37 | R6: 74.37 | V6: Sold | W6: FOOD | X6: FOOD | Y6: 0
A7: 6 | B7: 45903 | C7: 9 | D7: Week 01 | G7: HEALTHY FOOD | H7: 0 | I7: REV-NON ALCOHOL | J7: Revenue Non Alcohol | K7: 0 | L7: 0 | M7: 1 | N7: 0 | O7: 57.07 | R7: 57.07 | V7: Sold | W7: BEVERAGE NON-ALOCOHOL | X7: BEVERAGE NON-ALOCOHOL | Y7: 0
A8: 7 | G8: HEALTHY FOOD | H8: 0 | I8: REV-FOOD | J8: Revenue Food | K8: 0 | L8: 0 | M8: 1 | N8: 0 | R8: 0 | V8: Sold | W8: FOOD | X8: FOOD | Y8: 0
A9: 8 | G9: HEALTHY FOOD | H9: 0 | I9: REV-NON ALCOHOL | J9: Revenue Non Alcohol | K9: 0 | L9: 0 | M9: 1 | N9: 0 | R9: 0 | V9: Sold | W9: BEVERAGE NON-ALOCOHOL | X9: BEVERAGE NON-ALOCOHOL | Y9: 0
A10: 9 | G10: HEALTHY FOOD | H10: 0 | I10: REV-FOOD | J10: Revenue Food | K10: 0 | L10: 0 | M10: 1 | N10: 0 | R10: 0 | V10: Sold | W10: FOOD | X10: FOOD | Y10: 0
A11: 10 | G11: HEALTHY FOOD | H11: 0 | I11: REV-NON ALCOHOL | J11: Revenue Non Alcohol | K11: 0 | L11: 0 | M11: 1 | N11: 0 | R11: 0 | V11: Sold | W11: BEVERAGE NON-ALOCOHOL | X11: BEVERAGE NON-ALOCOHOL | Y11: 0
A12: 11 | G12: HEALTHY FOOD | H12: 0 | I12: REV-FOOD | J12: Revenue Food | K12: 0 | L12: 0 | M12: 1 | N12: 0 | R12: 0 | V12: Sold | W12: FOOD | X12: FOOD | Y12: 0
A13: 12 | G13: HEALTHY FOOD | H13: 0 | I13: REV-NON ALCOHOL | J13: Revenue Non Alcohol | K13: 0 | L13: 0 | M13: 1 | N13: 0 | R13: 0 | V13: Sold | W13: BEVERAGE NON-ALOCOHOL | X13: BEVERAGE NON-ALOCOHOL | Y13: 0
A14: 13 | G14: HEALTHY FOOD | H14: 0 | I14: REV-FOOD | J14: Revenue Food | K14: 0 | L14: 0 | M14: 1 | N14: 0 | R14: 0 | V14: Sold | W14: FOOD | X14: FOOD | Y14: 0
A15: 14 | G15: HEALTHY FOOD | H15: 0 | I15: REV-NON ALCOHOL | J15: Revenue Non Alcohol | K15: 0 | L15: 0 | M15: 1 | N15: 0 | R15: 0 | V15: Sold | W15: BEVERAGE NON-ALOCOHOL | X15: BEVERAGE NON-ALOCOHOL | Y15: 0
A16: 15 | G16: HEALTHY FOOD | H16: 0 | I16: REV-FOOD | J16: Revenue Food | K16: 0 | L16: 0 | M16: 1 | N16: 0 | R16: 0 | V16: Sold | W16: FOOD | X16: FOOD | Y16: 0
A17: 16 | G17: HEALTHY FOOD | H17: 0 | I17: REV-NON ALCOHOL | J17: Revenue Non Alcohol | K17: 0 | L17: 0 | M17: 1 | N17: 0 | R17: 0 | V17: Sold | W17: BEVERAGE NON-ALOCOHOL | X17: BEVERAGE NON-ALOCOHOL | Y17: 0
A18: 17 | G18: HEALTHY FOOD | H18: 0 | I18: REV-FOOD | J18: Revenue Food | K18: 0 | L18: 0 | M18: 1 | N18: 0 | R18: 0 | V18: Sold | W18: FOOD | X18: FOOD | Y18: 0
A19: 18 | G19: HEALTHY FOOD | H19: 0 | I19: REV-NON ALCOHOL | J19: Revenue Non Alcohol | K19: 0 | L19: 0 | M19: 1 | N19: 0 | R19: 0 | V19: Sold | W19: BEVERAGE NON-ALOCOHOL | X19: BEVERAGE NON-ALOCOHOL | Y19: 0
... A61: 60 | G61: HEALTHY FOOD | H61: 0 | I61: REV-NON ALCOHOL | J61: Revenue Non Alcohol | K61: 0 | L61: 0 | M61: 1 | N61: 0 | R61: 0 | V61: Sold | W61: BEVERAGE NON-ALOCOHOL | X61: BEVERAGE NON-ALOCOHOL | Y61: 0
A62: 61 | G62: HEALTHY FOOD | H62: 0 | I62: REV-FOOD | J62: Revenue Food | K62: 0 | L62: 0 | M62: 1 | N62: 0 | R62: 0 | W62: FOOD | X62: FOOD | Y62: 0
A63: 62 | G63: HEALTHY FOOD | H63: 0 | I63: REV-NON ALCOHOL | J63: Revenue Non Alcohol | K63: 0 | L63: 0 | M63: 1 | N63: 0 | R63: 0 | W63: BEVERAGE NON-ALOCOHOL | X63: BEVERAGE NON-ALOCOHOL | Y63: 0
A64: 1 | B64: 45901 | C64: 9 | D64: Week 01 | E64: PO30955 | F64: DN-010901 | G64: E-MART24 BKK1 | H64: F0103010009 | I64: CSW-0001 | J64: Tuna & Egg Sandwich | K64: 1BOX*2PCS | L64: BOX | M64: 2 | O64: 1.5 | R64: 3 | V64: Sold | W64: FOOD | X64: Sandwich | Y64: PO309551
A65: 2 | B65: 45901 | C65: 9 | D65: Week 01 | E65: PO30955 | F65: DN-010901 | G65: E-MART24 BKK1 | H65: F0103010010 | I65: CSW-0002 | J65: Ham & Corn Sandwich | K65: 1BOX*2PCS | L65: BOX | M65: 2 | O65: 1.5 | R65: 3 | V65: Sold | W65: FOOD | X65: Sandwich | Y65: PO309552
A66: 3 | B66: 45901 | C66: 9 | D66: Week 01 | E66: PO30955 | F66: DN-010901 | G66: E-MART24 BKK1 | H66: F0103010011 | I66: CSW-0003 | J66: Sausage & Freid Egg Sandwich | K66: 1BOX*2PCS | L66: BOX | M66: 2 | O66: 1.5 | R66: 3 | W66: FOOD | X66: Sandwich | Y66: PO309553
A67: 4 | B67: 45901 | C67: 9 | D67: Week 01 | E67: PO30955 | F67: DN-010901 | G67: E-MART24 BKK1 | H67: F0103010012 | I67: CSW-0004 | J67: Chicken Sandwich | K67: 1BOX*2PCS | L67: BOX | M67: 2 | O67: 1.5 | R67: 3 | V67: Sold | W67: FOOD | X67: Sandwich | Y67: PO309554
A68: 5 | B68: 45901 | C68: 9 | D68: Week 01 | E68: PO30955 | F68: DN-010901 | G68: E-MART24 BKK1 | H68: F0101010017 | I68: KL-0001 | J68: Bulgogi Dosirak-KL-0001 | K68: 1BOX*1Portion | L68: BOX | M68: 2 | O68: 2.2 | R68: 4.4 | V68: Sold | W68: FOOD | X68: Korean Lunch Box | Y68: PO309555
A69: 6 | B69: 45901 | C69: 9 | D69: Week 01 | E69: PO30955 | F69: DN-010901 | G69: E-MART24 BKK1 | H69: F0101010015 | I69: KL-0003 | J69: Japchae Dakgangjeong Dosirak-KL-0003 | K69: 1BOX*1Portion | L69: BOX | M69: 2 | O69: 2.6 | R69: 5.2 | V69: Sold | W69: FOOD | X69: Korean Lunch Box | Y69: PO309556
A70: 7 | B70: 45901 | C70: 9 | D70: Week 01 | E70: PO30955 | F70: DN-010901 | G70: E-MART24 BKK1 | H70: F0101010016 | I70: KL-0002 | J70: Stir Fried Spicy Pork Dosirak-KL-0002 | K70: 1BOX*1Portion | L70: BOX | M70: 2 | O70: 2.38 | R70: 4.76 | V70: Sold | W70: FOOD | X70: Korean Lunch Box | Y70: PO309557
A71: 8 | B71: 45901 | C71: 9 | D71: Week 01 | E71: PO30955 | F71: DN-010901 | G71: E-MART24 BKK1 | H71: F0103010013 | I71: SS-0002 | J71: Maki Crab & Chicken Egg | K71: 1BOX*6PCS | L71: Box | M71: 2 | O71: 1.21 | R71: 2.42 | V71: Sold | W71: FOOD | X71: Sushi | Y71: PO309558
A72: 9 | B72: 45901 | C72: 9 | D72: Week 01 | E72: PO30955 | F72: DN-010901 | G72: E-MART24 BKK1 | H72: F0103010014 | I72: SS-0004 | J72: Maki Cali & Tuna Roll | K72: 1BOX*3PCS | L72: Box | M72: 2 | O72: 1.21 | R72: 2.42 | V72: Sold | W72: FOOD | X72: Sushi | Y72: PO309559
A73: 10 | B73: 45901 | C73: 9 | D73: Week 01 | E73: PO30959 | F73: DN-010902 | G73: E-MART24 BKK1 | H73: 900029 | I73: HF-0001 | J73: BEEF LOK LAK WITH RICE (បាយ​ ឡុកឡាក់សាច់គោ) | K73: 1BOX*1Portion | L73: BOX | M73: 2 | O73: 1.668 | R73: 3.336 | V73: Sold | W73: FOOD | X73: Khmer Food | Y73: PO309591
A74: 11 | B74: 45901 | C74: 9 | D74: Week 01 | E74: PO30959 | F74: DN-010902 | G74: E-MART24 BKK1 | H74: 900027 | I74: HF-0002 | J74: STIR FRIED MINCED PORK HOT BASIL WITH RICE (បាយ សាច់ជ្រូកចិញ្រ្ចាំឆាម្រះព្រៅ) | K74: 1BOX*1Portion | L74: BOX | M74: 2 | O74: 1.2024 | R74: 2.4048 | V74: Sold | W74: FOOD | X74: Khmer Food | Y74: PO309592
A75: 12 | B75: 45901 | C75: 9 | D75: Week 01 | E75: PO30959 | F75: DN-010902 | G75: E-MART24 BKK1 | H75: 900031 | I75: HF-0008 | J75: ROASTED DUCK WITH RICE (បាយ ទាខ្វៃ) | K75: 1BOX*1Portion | L75: BOX | M75: 2 | O75: 1.4784 | R75: 2.9568 | V75: Sold | W75: FOOD | X75: Khmer Food | Y75: PO309593
A76: 13 | B76: 45901 | C76: 9 | D76: Week 01 | E76: PO30959 | F76: DN-010902 | G76: E-MART24 BKK1 | H76: 900032 | I76: HF-0004 | J76: STIR FRIED MINCED CHICKEN HOT BASIL WITH RICE (បាយ​ សាច់មាន់ចិញ្រ្ចាំឆាម្រះព្រៅ) | K76: 1BOX*1Portion | L76: BOX | M76: 2 | O76: 1.2984 | R76: 2.5968 | V76: Sold | W76: FOOD | X76: Khmer Food | Y76: PO309594
A77: 14 | B77: 45901 | C77: 9 | D77: Week 01 | E77: PO30959 | F77: DN-010902 | G77: E-MART24 BKK1 | H77: 900028 | I77: HF-0005 | J77: STIR FRIED MINCED PORK EGGPLANT WITH RICE (បាយ សាច់ជ្រូកចិញ្ច្រាំឆាត្រប់វែង) | K77: 1BOX*1Portion | L77: BOX | M77: 2 | O77: 1.0104 | R77: 2.0208 | V77: Sold | W77: FOOD | X77: Khmer Food | Y77: PO309595
A78: 15 | B78: 45901 | C78: 9 | D78: Week 01 | E78: PO30959 | F78: DN-010902 | G78: E-MART24 BKK1 | H78: 900038 | I78: HF-0010 | J78: ROATED PORK BELLY WITH RICE (បាយ សាច់ជ្រូក៣ជាន់) | K78: 1BOX*1Portion | L78: BOX | M78: 2 | O78: 1.092 | R78: 2.184 | V78: Sold | W78: FOOD | X78: Khmer Food | Y78: PO309596
... A82: 19 | B82: 45901 | C82: 9 | D82: Week 01 | E82: PO30959 | F82: DN-010902 | G82: E-MART24 BKK1 | H82: F0101010018 | I82: HF-0027 | J82: Salmon Fried Rice (បា​យឆា សាលម៉ុន) | K82: 1BOX*1Portion | L82: BOX | M82: 1 | O82: 1.6 | R82: 1.6 | V82: Sold | W82: FOOD | X82: Khmer Food | Y82: PO3095910
A83: 20 | B83: 45901 | C83: 9 | D83: Week 01 | E83: PO30959 | F83: DN-010902 | G83: E-MART24 BKK1 | H83: F0101010019 | I83: HF-0028 | J83: Crab Fried Rice (បាយឆា ក្ដាម) | K83: 1BOX*1Portion | L83: BOX | M83: 1 | O83: 1.6 | R83: 1.6 | W83: FOOD | X83: Khmer Food | Y83: PO3095911
A84: 21 | B84: 45901 | C84: 9 | D84: Week 01 | E84: PO30959 | F84: DN-010902 | G84: E-MART24 BKK1 | H84: 900152 | I84: V-0102 | J84: Lettuce Iceberg | K84: KG | L84: KG | M84: 1 | O84: 3.12 | R84: 3.12 | W84: FOOD | X84: Fruits & Veggies / Veggies | Y84: PO3095912
...

Sheet MASTER LIST
A1: Nº | B1: Item Code | C1: Barcode | D1: Item Name | E1: ITEM NAME in Khmer | F1: Supplier Name | G1: Category | H1: Sub Category | I1: UOM | J1: Packing Size | K1: Unit Cost | L1: Invoice Price | M1: Lead Times | N1: Par Stock | O1: NUB | P1: Nub2 | Q1: Name | R1: Data Search | S1: Master Name | U1: Date | W1: NUB | X1: Nub2 | Y1: Supplied Name | Z1: Data Search | AA1: Master Name | AC1: NUB | AD1: Nub2 | AE1: Location | AF1: Data Search | AG1: Master Name | AI1: Using Period | AJ1: Reason
A2: {=ROW(1:1)} -> 1 | B2: C-0022 | C2: 900277 | D2: Plastic Glove (ស្រោមដៃថង់) | F2: CENTRAL KITCHEN | G2: NON-FOOD | H2: NON-FOOD | I2: PKT | J2: PKT*100PCS | K2: 0.72 | M2: 1 | N2: 10 | O2: =IF(ISNUMBER(SEARCH('Data Entry'!$J$3,$Q2)),MAX($O$1:$O1)+1,0) -> 0 | P2: =IF(ISNUMBER(SEARCH('Data Entry'!$J$3,$Q2)),MAX($P$1:$P1)+1,0) -> 0 | Q2: =Table2[[#This Row],[Item Name ]] -> Plastic Glove (ស្រោមដៃថង់) | R2: =IFERROR(VLOOKUP(ROWS($R$2:$R2),Table2[[Nub2]:[Name]],2,0),"") -> Set Plastic Spoon & Fork (ឈុតស្លាបព្រា សម) | W2: =IF(ISNUMBER(SEARCH('Data Entry'!$J$3,$Y2)),MAX($W$1:$W1)+1,0) -> 0 | X2: =IF(ISNUMBER(SEARCH('Data Entry'!$J$3,$Y2)),MAX($X$1:$X1)+1,0) -> 0 | Y2: 168 Curtain Beauty | Z2: =IFERROR(VLOOKUP(ROWS($Z$2:$Z2),Table4[[Nub2]:[Supplied Name]],2,0),"") | AA2: =OFFSET($Z$2,,,COUNTIF($Z$2:$Z$25,"?*")) -> #REF! | AC2: =IF(ISNUMBER(SEARCH('Data Entry'!$J$3,$AE2)),MAX($AC$1:$AC1)+1,0) -> 0 | AD2: =IF(ISNUMBER(SEARCH('Data Entry'!$J$3,$AE2)),MAX($AD$1:$AD1)+1,0) -> 0 | AE2: Catering | AF2: =IFERROR(VLOOKUP(ROWS($Z$2:$Z2),Table5[[#All],[Nub2]:[Location ]],2,0),"") | AG2: =OFFSET($AF$2,,,COUNTIF($AF$2:$AF$25,"?*")) -> #REF! | AI2: 1 Day | AJ2: Expried
A3: {=ROW(2:2)} -> 2 | B3: C-0023 | C3: 900278 | D3: Latex Glove (Top) ស្រោមដៃពេទ្យ | F3: CENTRAL KITCHEN | G3: NON-FOOD | H3: NON-FOOD | I3: PKT | J3: 1PKT*100PCS | K3: 5.16 | M3: 1 | N3: 10 | O3: =IF(ISNUMBER(SEARCH('Data Entry'!$J$3,$Q3)),MAX($O$1:$O2)+1,0) -> 0 | P3: =IF(ISNUMBER(SEARCH('Data Entry'!$J$3,$Q3)),MAX($P$1:$P2)+1,0) -> 0 | Q3: =Table2[[#This Row],[Item Name ]] -> Latex Glove (Top) ស្រោមដៃពេទ្យ | R3: =IFERROR(VLOOKUP(ROWS($R$2:$R3),Table2[[Nub2]:[Name]],2,0),"") | W3: =IF(ISNUMBER(SEARCH('Data Entry'!$J$3,$Y3)),MAX($W$1:$W2)+1,0) -> 0 | X3: =IF(ISNUMBER(SEARCH('Data Entry'!$J$3,$Y3)),MAX($X$1:$X2)+1,0) -> 0 | Y3: 168 Curtain BeautyLOSS | Z3: =IFERROR(VLOOKUP(ROWS($Z$2:$Z3),Table4[[Nub2]:[Supplied Name]],2,0),"") | AA3: =OFFSET($Z$2,,,COUNTIF($Z$2:$Z$25,"?*")) -> #REF! | AC3: =IF(ISNUMBER(SEARCH('Data Entry'!$J$3,$AE3)),MAX($AC$1:$AC2)+1,0) -> 0 | AD3: =IF(ISNUMBER(SEARCH('Data Entry'!$J$3,$AE3)),MAX($AD$1:$AD2)+1,0) -> 0 | AE3: Central Bakery | AF3: =IFERROR(VLOOKUP(ROWS($Z$2:$Z3),Table5[[#All],[Nub2]:[Location ]],2,0),"") | AG3: =OFFSET($AF$2,,,COUNTIF($AF$2:$AF$25,"?*")) -> #REF! | AI3: 2 Day | AJ3: Nealy Exp
A4: {=ROW(3:3)} -> 3 | B4: DF-0001 | C4: 900136 | D4: Grined Pork Jerky (orginal) | F4: CENTRAL KITCHEN | G4: FOOD | H4: Dry Food | I4: PKT | J4: 1PKT*30G (6 Sliced) | K4: =6.57/10 -> 0.657 | M4: 1 | N4: 10 | O4: =IF(ISNUMBER(SEARCH('Data Entry'!$J$3,$Q4)),MAX($O$1:$O3)+1,0) -> 0 | P4: =IF(ISNUMBER(SEARCH('Data Entry'!$J$3,$Q4)),MAX($P$1:$P3)+1,0) -> 0 | Q4: =Table2[[#This Row],[Item Name ]] -> Grined Pork Jerky (orginal) | R4: =IFERROR(VLOOKUP(ROWS($R$2:$R4),Table2[[Nub2]:[Name]],2,0),"") | W4: =IF(ISNUMBER(SEARCH('Data Entry'!$J$3,$Y4)),MAX($W$1:$W3)+1,0) -> 0 | X4: =IF(ISNUMBER(SEARCH('Data Entry'!$J$3,$Y4)),MAX($X$1:$X3)+1,0) -> 0 | Y4: 3PLE FARMS CO., LTD | Z4: =IFERROR(VLOOKUP(ROWS($Z$2:$Z4),Table4[[Nub2]:[Supplied Name]],2,0),"") | AA4: =OFFSET($Z$2,,,COUNTIF($Z$2:$Z$25,"?*")) -> #REF! | AC4: =IF(ISNUMBER(SEARCH('Data Entry'!$J$3,$AE4)),MAX($AC$1:$AC3)+1,0) -> 0 | AD4: =IF(ISNUMBER(SEARCH('Data Entry'!$J$3,$AE4)),MAX($AD$1:$AD3)+1,0) -> 0 | AE4: Central Kitchen | AF4: =IFERROR(VLOOKUP(ROWS($Z$2:$Z4),Table5[[#All],[Nub2]:[Location ]],2,0),"") | AG4: =OFFSET($AF$2,,,COUNTIF($AF$2:$AF$25,"?*")) -> #REF! | AI4: 3 Day | AJ4: Wrong Brand
A5: {=ROW(4:4)} -> 4 | B5: DF-0002 | C5: 900137 | D5: Grined Pork Jerky (spicy) | F5: CENTRAL KITCHEN | G5: FOOD | H5: Dry Food | I5: PKT | J5: 1PKT*30G (6 Sliced) | K5: =6.64/10 -> 0.664 | M5: 1 | N5: 10 | O5: =IF(ISNUMBER(SEARCH('Data Entry'!$J$3,$Q5)),MAX($O$1:$O4)+1,0) -> 0 | P5: =IF(ISNUMBER(SEARCH('Data Entry'!$J$3,$Q5)),MAX($P$1:$P4)+1,0) -> 0 | Q5: =Table2[[#This Row],[Item Name ]] -> Grined Pork Jerky (spicy) | R5: =IFERROR(VLOOKUP(ROWS($R$2:$R5),Table2[[Nub2]:[Name]],2,0),"") | W5: =IF(ISNUMBER(SEARCH('Data Entry'!$J$3,$Y5)),MAX($W$1:$W4)+1,0) -> 0 | X5: =IF(ISNUMBER(SEARCH('Data Entry'!$J$3,$Y5)),MAX($X$1:$X4)+1,0) -> 0 | Y5: 62 Printing Service | Z5: =IFERROR(VLOOKUP(ROWS($Z$2:$Z5),Table4[[Nub2]:[Supplied Name]],2,0),"") | AA5: =OFFSET($Z$2,,,COUNTIF($Z$2:$Z$25,"?*")) -> #REF! | AC5: =IF(ISNUMBER(SEARCH('Data Entry'!$J$3,$AE5)),MAX($AC$1:$AC4)+1,0) -> 0 | AD5: =IF(ISNUMBER(SEARCH('Data Entry'!$J$3,$AE5)),MAX($AD$1:$AD4)+1,0) -> 0 | AE5: Fine Dining-TK | AF5: =IFERROR(VLOOKUP(ROWS($Z$2:$Z5),Table5[[#All],[Nub2]:[Location ]],2,0),"") | AG5: =OFFSET($AF$2,,,COUNTIF($AF$2:$AF$25,"?*")) -> #REF! | AI5: 7 Day | AJ5: Wrong Size
A6: {=ROW(5:5)} -> 5 | B6: DF-0003 | C6: 900138 | D6: Grined Beef Jerky (orginal) | F6: CENTRAL KITCHEN | G6: FOOD | H6: Dry Food | I6: PKT | J6: 1PKT*30G (6 Sliced) | K6: =14.274/10 -> 1.4274 | M6: 1 | N6: 10 | O6: =IF(ISNUMBER(SEARCH('Data Entry'!$J$3,$Q6)),MAX($O$1:$O5)+1,0) -> 0 | P6: =IF(ISNUMBER(SEARCH('Data Entry'!$J$3,$Q6)),MAX($P$1:$P5)+1,0) -> 0 | Q6: =Table2[[#This Row],[Item Name ]] -> Grined Beef Jerky (orginal) | R6: =IFERROR(VLOOKUP(ROWS($R$2:$R6),Table2[[Nub2]:[Name]],2,0),"") | W6: =IF(ISNUMBER(SEARCH('Data Entry'!$J$3,$Y6)),MAX($W$1:$W5)+1,0) -> 0 | X6: =IF(ISNUMBER(SEARCH('Data Entry'!$J$3,$Y6)),MAX($X$1:$X5)+1,0) -> 0 | Y6: 800 SUPER GAEA (CAMBODIA) CO., LTD | Z6: =IFERROR(VLOOKUP(ROWS($Z$2:$Z6),Table4[[Nub2]:[Supplied Name]],2,0),"") | AA6: =OFFSET($Z$2,,,COUNTIF($Z$2:$Z$25,"?*")) -> #REF! | AC6: =IF(ISNUMBER(SEARCH('Data Entry'!$J$3,$AE6)),MAX($AC$1:$AC5)+1,0) -> 0 | AD6: =IF(ISNUMBER(SEARCH('Data Entry'!$J$3,$AE6)),MAX($AD$1:$AD5)+1,0) -> 0 | AE6: Fun Crab - 271 Mega Mall | AF6: =IFERROR(VLOOKUP(ROWS($Z$2:$Z6),Table5[[#All],[Nub2]:[Location ]],2,0),"") | AG6: =OFFSET($AF$2,,,COUNTIF($AF$2:$AF$25,"?*")) -> #REF! | AI6: 15 Day | AJ6: Other
A7: {=ROW(6:6)} -> 6 | B7: DF-0004 | C7: 900139 | D7: Grined Beef Jerky (spicy) | F7: CENTRAL KITCHEN | G7: FOOD | H7: Dry Food | I7: PKT | J7: 1PKT*30G (6 Sliced) | K7: =14.38/10 -> 1.438 | M7: 1 | N7: 10 | O7: =IF(ISNUMBER(SEARCH('Data Entry'!$J$3,$Q7)),MAX($O$1:$O6)+1,0) -> 0 | P7: =IF(ISNUMBER(SEARCH('Data Entry'!$J$3,$Q7)),MAX($P$1:$P6)+1,0) -> 0 | Q7: =Table2[[#This Row],[Item Name ]] -> Grined Beef Jerky (spicy) | R7: =IFERROR(VLOOKUP(ROWS($R$2:$R7),Table2[[Nub2]:[Name]],2,0),"") | W7: =IF(ISNUMBER(SEARCH('Data Entry'!$J$3,$Y7)),MAX($W$1:$W6)+1,0) -> 0 | X7: =IF(ISNUMBER(SEARCH('Data Entry'!$J$3,$Y7)),MAX($X$1:$X6)+1,0) -> 0 | Y7: A.V.R (Asia Vehicle Rental) Co.,Ltd(AVR) | Z7: =IFERROR(VLOOKUP(ROWS($Z$2:$Z7),Table4[[Nub2]:[Supplied Name]],2,0),"") | AA7: =OFFSET($Z$2,,,COUNTIF($Z$2:$Z$25,"?*")) -> #REF! | AC7: =IF(ISNUMBER(SEARCH('Data Entry'!$J$3,$AE7)),MAX($AC$1:$AC6)+1,0) -> 0 | AD7: =IF(ISNUMBER(SEARCH('Data Entry'!$J$3,$AE7)),MAX($AD$1:$AD6)+1,0) -> 0 | AE7: Fun Crab - Aeon 2 | AF7: =IFERROR(VLOOKUP(ROWS($Z$2:$Z7),Table5[[#All],[Nub2]:[Location ]],2,0),"") | AG7: =OFFSET($AF$2,,,COUNTIF($AF$2:$AF$25,"?*")) -> #REF! | AI7: 30 Day | AJ7: Spoiled
A8: {=ROW(7:7)} -> 7 | B8: DF-0005 | C8: 900140 | D8: Char Siew Pork Jerky (Original) | F8: CENTRAL KITCHEN | G8: FOOD | H8: Dry Food | I8: PKT | J8: 1PKT*30G | K8: =5.51/10 -> 0.551 | M8: 1 | N8: 10 | O8: =IF(ISNUMBER(SEARCH('Data Entry'!$J$3,$Q8)),MAX($O$1:$O7)+1,0) -> 0 | P8: =IF(ISNUMBER(SEARCH('Data Entry'!$J$3,$Q8)),MAX($P$1:$P7)+1,0) -> 0 | Q8: =Table2[[#This Row],[Item Name ]] -> Char Siew Pork Jerky (Original) | R8: =IFERROR(VLOOKUP(ROWS($R$2:$R8),Table2[[Nub2]:[Name]],2,0),"") | W8: =IF(ISNUMBER(SEARCH('Data Entry'!$J$3,$Y8)),MAX($W$1:$W7)+1,0) -> 0 | X8: =IF(ISNUMBER(SEARCH('Data Entry'!$J$3,$Y8)),MAX($X$1:$X7)+1,0) -> 0 | Y8: A2 TRADING | Z8: =IFERROR(VLOOKUP(ROWS($Z$2:$Z8),Table4[[Nub2]:[Supplied Name]],2,0),"") | AA8: =OFFSET($Z$2,,,COUNTIF($Z$2:$Z$25,"?*")) -> #REF! | AC8: =IF(ISNUMBER(SEARCH('Data Entry'!$J$3,$AE8)),MAX($AC$1:$AC7)+1,0) -> 0 | AD8: =IF(ISNUMBER(SEARCH('Data Entry'!$J$3,$AE8)),MAX($AD$1:$AD7)+1,0) -> 0 | AE8: Fun Crab - Toul Tom Pong | AF8: =IFERROR(VLOOKUP(ROWS($Z$2:$Z8),Table5[[#All],[Nub2]:[Location ]],2,0),"") | AG8: =OFFSET($AF$2,,,COUNTIF($AF$2:$AF$25,"?*")) -> #REF! | AI8: Daily Use | AJ8: Suport operation
A9: {=ROW(8:8)} -> 8 | B9: DF-0006 | C9: 900141 | D9: Char Siew Pork Jerky (Spicy) | F9: CENTRAL KITCHEN | G9: FOOD | H9: Dry Food | I9: PKT | J9: 1PKT*30G | K9: =5.694/10 -> 0.5694 | M9: 1 | N9: 10 | O9: =IF(ISNUMBER(SEARCH('Data Entry'!$J$3,$Q9)),MAX($O$1:$O8)+1,0) -> 0 | P9: =IF(ISNUMBER(SEARCH('Data Entry'!$J$3,$Q9)),MAX($P$1:$P8)+1,0) -> 0 | Q9: =Table2[[#This Row],[Item Name ]] -> Char Siew Pork Jerky (Spicy) | R9: =IFERROR(VLOOKUP(ROWS($R$2:$R9),Table2[[Nub2]:[Name]],2,0),"") | W9: =IF(ISNUMBER(SEARCH('Data Entry'!$J$3,$Y9)),MAX($W$1:$W8)+1,0) -> 0 | X9: =IF(ISNUMBER(SEARCH('Data Entry'!$J$3,$Y9)),MAX($X$1:$X8)+1,0) -> 0 | Y9: ABC Green Supply Co., Ltd | Z9: =IFERROR(VLOOKUP(ROWS($Z$2:$Z9),Table4[[Nub2]:[Supplied Name]],2,0),"") | AA9: =OFFSET($Z$2,,,COUNTIF($Z$2:$Z$25,"?*")) -> #REF! | AC9: =IF(ISNUMBER(SEARCH('Data Entry'!$J$3,$AE9)),MAX($AC$1:$AC8)+1,0) -> 0 | AD9: =IF(ISNUMBER(SEARCH('Data Entry'!$J$3,$AE9)),MAX($AD$1:$AD8)+1,0) -> 0 | AE9: Fun Crab - Tuol Kork | AF9: =IFERROR(VLOOKUP(ROWS($Z$2:$Z9),Table5[[#All],[Nub2]:[Location ]],2,0),"") | AG9: =OFFSET($AF$2,,,COUNTIF($AF$2:$AF$25,"?*")) -> #REF!
A10: {=ROW(9:9)} -> 9 | B10: DF-0007 | C10: 900142 | D10: Dried beef (original) | F10: CENTRAL KITCHEN | G10: FOOD | H10: Dry Food | I10: PKT | J10: 1PKT*30G | K10: =8.4/10 -> 0.84 | M10: 1 | N10: 10 | O10: =IF(ISNUMBER(SEARCH('Data Entry'!$J$3,$Q10)),MAX($O$1:$O9)+1,0) -> 0 | P10: =IF(ISNUMBER(SEARCH('Data Entry'!$J$3,$Q10)),MAX($P$1:$P9)+1,0) -> 0 | Q10: =Table2[[#This Row],[Item Name ]] -> Dried beef (original) | R10: =IFERROR(VLOOKUP(ROWS($R$2:$R10),Table2[[Nub2]:[Name]],2,0),"") | W10: =IF(ISNUMBER(SEARCH('Data Entry'!$J$3,$Y10)),MAX($W$1:$W9)+1,0) -> 0 | X10: =IF(ISNUMBER(SEARCH('Data Entry'!$J$3,$Y10)),MAX($X$1:$X9)+1,0) -> 0 | Y10: ACCOUNTING AND AUDITING REGULATOR | Z10: =IFERROR(VLOOKUP(ROWS($Z$2:$Z10),Table4[[Nub2]:[Supplied Name]],2,0),"") | AA10: =OFFSET($Z$2,,,COUNTIF($Z$2:$Z$25,"?*")) -> #REF! | AC10: =IF(ISNUMBER(SEARCH('Data Entry'!$J$3,$AE10)),MAX($AC$1:$AC9)+1,0) -> 0 | AD10: =IF(ISNUMBER(SEARCH('Data Entry'!$J$3,$AE10)),MAX($AD$1:$AD9)+1,0) -> 0 | AE10: Guriru - Toulkok | AF10: =IFERROR(VLOOKUP(ROWS($Z$2:$Z10),Table5[[#All],[Nub2]:[Location ]],2,0),"") | AG10: =OFFSET($AF$2,,,COUNTIF($AF$2:$AF$25,"?*")) -> #REF!
A11: {=ROW(10:10)} -> 10 | B11: DF-0008 | C11: 900143 | D11: Dried beef (spicy) | F11: CENTRAL KITCHEN | G11: FOOD | H11: Dry Food | I11: PKT | J11: 1PKT*30G | K11: =8.43/10 -> 0.843 | M11: 1 | N11: 10 | O11: =IF(ISNUMBER(SEARCH('Data Entry'!$J$3,$Q11)),MAX($O$1:$O10)+1,0) -> 0 | P11: =IF(ISNUMBER(SEARCH('Data Entry'!$J$3,$Q11)),MAX($P$1:$P10)+1,0) -> 0 | Q11: =Table2[[#This Row],[Item Name ]] -> Dried beef (spicy) | R11: =IFERROR(VLOOKUP(ROWS($R$2:$R11),Table2[[Nub2]:[Name]],2,0),"") | W11: =IF(ISNUMBER(SEARCH('Data Entry'!$J$3,$Y11)),MAX($W$1:$W10)+1,0) -> 0 | X11: =IF(ISNUMBER(SEARCH('Data Entry'!$J$3,$Y11)),MAX($X$1:$X10)+1,0) -> 0 | Y11: ACE ZAPA | Z11: =IFERROR(VLOOKUP(ROWS($Z$2:$Z11),Table4[[Nub2]:[Supplied Name]],2,0),"") | AA11: =OFFSET($Z$2,,,COUNTIF($Z$2:$Z$25,"?*")) -> #REF! | AC11: =IF(ISNUMBER(SEARCH('Data Entry'!$J$3,$AE11)),MAX($AC$1:$AC10)+1,0) -> 0 | AD11: =IF(ISNUMBER(SEARCH('Data Entry'!$J$3,$AE11)),MAX($AD$1:$AD10)+1,0) -> 0 | AE11: Hiko - Euro Park | AF11: =IFERROR(VLOOKUP(ROWS($Z$2:$Z11),Table5[[#All],[Nub2]:[Location ]],2,0),"") | AG11: =OFFSET($AF$2,,,COUNTIF($AF$2:$AF$25,"?*")) -> #REF!
A12: {=ROW(11:11)} -> 11 | B12: DF-0009 | C12: 900144 | D12: Beef sausage (Steamed & vacuum) | F12: CENTRAL KITCHEN | G12: FOOD | H12: Dry Food | I12: PKT | J12: 1PKT*45G (1 PCS) | K12: =8.64/12 -> 0.72 | M12: 1 | N12: 10 | O12: =IF(ISNUMBER(SEARCH('Data Entry'!$J$3,$Q12)),MAX($O$1:$O11)+1,0) -> 0 | P12: =IF(ISNUMBER(SEARCH('Data Entry'!$J$3,$Q12)),MAX($P$1:$P11)+1,0) -> 0 | Q12: =Table2[[#This Row],[Item Name ]] -> Beef sausage (Steamed & vacuum) | R12: =IFERROR(VLOOKUP(ROWS($R$2:$R12),Table2[[Nub2]:[Name]],2,0),"") | W12: =IF(ISNUMBER(SEARCH('Data Entry'!$J$3,$Y12)),MAX($W$1:$W11)+1,0) -> 0 | X12: =IF(ISNUMBER(SEARCH('Data Entry'!$J$3,$Y12)),MAX($X$1:$X11)+1,0) -> 0 | Y12: ACLEDA BANK PLC. | Z12: =IFERROR(VLOOKUP(ROWS($Z$2:$Z12),Table4[[Nub2]:[Supplied Name]],2,0),"") | AA12: =OFFSET($Z$2,,,COUNTIF($Z$2:$Z$25,"?*")) -> #REF! | AC12: =IF(ISNUMBER(SEARCH('Data Entry'!$J$3,$AE12)),MAX($AC$1:$AC11)+1,0) -> 0 | AD12: =IF(ISNUMBER(SEARCH('Data Entry'!$J$3,$AE12)),MAX($AD$1:$AD11)+1,0) -> 0 | AE12: Hiko - Noro Mall | AF12: =IFERROR(VLOOKUP(ROWS($Z$2:$Z12),Table5[[#All],[Nub2]:[Location ]],2,0),"") | AG12: =OFFSET($AF$2,,,COUNTIF($AF$2:$AF$25,"?*")) -> #REF!
A13: {=ROW(12:12)} -> 12 | B13: DF-0010 | C13: 900145 | D13: Pork sausage (Steamed & Vacuum) | F13: CENTRAL KITCHEN | G13: FOOD | H13: Dry Food | I13: PKT | J13: 1PKT*45G (1 PCS) | K13: =8.64/12 -> 0.72 | M13: 1 | N13: 10 | O13: =IF(ISNUMBER(SEARCH('Data Entry'!$J$3,$Q13)),MAX($O$1:$O12)+1,0) -> 0 | P13: =IF(ISNUMBER(SEARCH('Data Entry'!$J$3,$Q13)),MAX($P$1:$P12)+1,0) -> 0 | Q13: =Table2[[#This Row],[Item Name ]] -> Pork sausage (Steamed & Vacuum) | R13: =IFERROR(VLOOKUP(ROWS($R$2:$R13),Table2[[Nub2]:[Name]],2,0),"") | W13: =IF(ISNUMBER(SEARCH('Data Entry'!$J$3,$Y13)),MAX($W$1:$W12)+1,0) -> 0 | X13: =IF(ISNUMBER(SEARCH('Data Entry'!$J$3,$Y13)),MAX($X$1:$X12)+1,0) -> 0 | Y13: ACM HR Consultancy | Z13: =IFERROR(VLOOKUP(ROWS($Z$2:$Z13),Table4[[Nub2]:[Supplied Name]],2,0),"") | AA13: =OFFSET($Z$2,,,COUNTIF($Z$2:$Z$25,"?*")) -> #REF! | AC13: =IF(ISNUMBER(SEARCH('Data Entry'!$J$3,$AE13)),MAX($AC$1:$AC12)+1,0) -> 0 | AD13: =IF(ISNUMBER(SEARCH('Data Entry'!$J$3,$AE13)),MAX($AD$1:$AD12)+1,0) -> 0 | AE13: Hiko 271- Mega Mall | AF13: =IFERROR(VLOOKUP(ROWS($Z$2:$Z13),Table5[[#All],[Nub2]:[Location ]],2,0),"") | AG13: =OFFSET($AF$2,,,COUNTIF($AF$2:$AF$25,"?*")) -> #REF!
A14: {=ROW(13:13)} -> 13 | B14: DF-0011 | C14: 900146 | D14: Fish Kakerm | G14: FOOD | H14: Dry Food | I14: PKT | J14: 1PKT*150G | M14: 1 | N14: 10 | O14: =IF(ISNUMBER(SEARCH('Data Entry'!$J$3,$Q14)),MAX($O$1:$O13)+1,0) -> 0 | P14: =IF(ISNUMBER(SEARCH('Data Entry'!$J$3,$Q14)),MAX($P$1:$P13)+1,0) -> 0 | Q14: =Table2[[#This Row],[Item Name ]] -> Fish Kakerm | R14: =IFERROR(VLOOKUP(ROWS($R$2:$R14),Table2[[Nub2]:[Name]],2,0),"") | W14: =IF(ISNUMBER(SEARCH('Data Entry'!$J$3,$Y14)),MAX($W$1:$W13)+1,0) -> 0 | X14: =IF(ISNUMBER(SEARCH('Data Entry'!$J$3,$Y14)),MAX($X$1:$X13)+1,0) -> 0 | Y14: ACTIVE COMMUNICATIONS CO.,LTD | Z14: =IFERROR(VLOOKUP(ROWS($Z$2:$Z14),Table4[[Nub2]:[Supplied Name]],2,0),"") | AA14: =OFFSET($Z$2,,,COUNTIF($Z$2:$Z$25,"?*")) -> #REF! | AC14: =IF(ISNUMBER(SEARCH('Data Entry'!$J$3,$AE14)),MAX($AC$1:$AC13)+1,0) -> 0 | AD14: =IF(ISNUMBER(SEARCH('Data Entry'!$J$3,$AE14)),MAX($AD$1:$AD13)+1,0) -> 0 | AE14: Hiko-Design Village | AF14: =IFERROR(VLOOKUP(ROWS($Z$2:$Z14),Table5[[#All],[Nub2]:[Location ]],2,0),"") | AG14: =OFFSET($AF$2,,,COUNTIF($AF$2:$AF$25,"?*")) -> #REF!
A15: {=ROW(14:14)} -> 14 | B15: DF-0012 | C15: 900147 | D15: Cashew nuts (original) | F15: CENTRAL KITCHEN | G15: FOOD | H15: Dry Food | I15: PKT | J15: 1PKT*150G | M15: 1 | N15: 10 | O15: =IF(ISNUMBER(SEARCH('Data Entry'!$J$3,$Q15)),MAX($O$1:$O14)+1,0) -> 0 | P15: =IF(ISNUMBER(SEARCH('Data Entry'!$J$3,$Q15)),MAX($P$1:$P14)+1,0) -> 0 | Q15: =Table2[[#This Row],[Item Name ]] -> Cashew nuts (original) | R15: =IFERROR(VLOOKUP(ROWS($R$2:$R15),Table2[[Nub2]:[Name]],2,0),"") | W15: =IF(ISNUMBER(SEARCH('Data Entry'!$J$3,$Y15)),MAX($W$1:$W14)+1,0) -> 0 | X15: =IF(ISNUMBER(SEARCH('Data Entry'!$J$3,$Y15)),MAX($X$1:$X14)+1,0) -> 0 | Y15: ADVANCED BANK OF ASIA LIMITED | Z15: =IFERROR(VLOOKUP(ROWS($Z$2:$Z15),Table4[[Nub2]:[Supplied Name]],2,0),"") | AA15: =OFFSET($Z$2,,,COUNTIF($Z$2:$Z$25,"?*")) -> #REF! | AC15: =IF(ISNUMBER(SEARCH('Data Entry'!$J$3,$AE15)),MAX($AC$1:$AC14)+1,0) -> 0 | AD15: =IF(ISNUMBER(SEARCH('Data Entry'!$J$3,$AE15)),MAX($AD$1:$AD14)+1,0) -> 0 | AE15: Mras Prov - Borey Keyla | AF15: =IFERROR(VLOOKUP(ROWS($Z$2:$Z15),Table5[[#All],[Nub2]:[Location ]],2,0),"") | AG15: =OFFSET($AF$2,,,COUNTIF($AF$2:$AF$25,"?*")) -> #REF!
A16: {=ROW(15:15)} -> 15 | B16: DF-0013 | C16: 900148 | D16: Cashew nuts (spicy) | F16: CENTRAL KITCHEN | G16: FOOD | H16: Dry Food | I16: PKT | J16: 1PKT*150G | M16: 1 | N16: 10 | O16: =IF(ISNUMBER(SEARCH('Data Entry'!$J$3,$Q16)),MAX($O$1:$O15)+1,0) -> 0 | P16: =IF(ISNUMBER(SEARCH('Data Entry'!$J$3,$Q16)),MAX($P$1:$P15)+1,0) -> 0 | Q16: =Table2[[#This Row],[Item Name ]] -> Cashew nuts (spicy) | R16: =IFERROR(VLOOKUP(ROWS($R$2:$R16),Table2[[Nub2]:[Name]],2,0),"") | W16: =IF(ISNUMBER(SEARCH('Data Entry'!$J$3,$Y16)),MAX($W$1:$W15)+1,0) -> 0 | X16: =IF(ISNUMBER(SEARCH('Data Entry'!$J$3,$Y16)),MAX($X$1:$X15)+1,0) -> 0 | Y16: ADVERTISING DECORATION & PRINTING | Z16: =IFERROR(VLOOKUP(ROWS($Z$2:$Z16),Table4[[Nub2]:[Supplied Name]],2,0),"") | AA16: =OFFSET($Z$2,,,COUNTIF($Z$2:$Z$25,"?*")) -> #REF! | AC16: =IF(ISNUMBER(SEARCH('Data Entry'!$J$3,$AE16)),MAX($AC$1:$AC15)+1,0) -> 0 | AD16: =IF(ISNUMBER(SEARCH('Data Entry'!$J$3,$AE16)),MAX($AD$1:$AD15)+1,0) -> 0 | AE16: Neptune - Seafood | AF16: =IFERROR(VLOOKUP(ROWS($Z$2:$Z16),Table5[[#All],[Nub2]:[Location ]],2,0),"") | AG16: =OFFSET($AF$2,,,COUNTIF($AF$2:$AF$25,"?*")) -> #REF!
A17: {=ROW(16:16)} -> 16 | B17: DF-0014 | C17: 900149 | D17: Big Peanuts (original) | F17: CENTRAL KITCHEN | G17: FOOD | H17: Dry Food | I17: PKT | J17: 1PKT*150G | K17: 0.76 | M17: 1 | N17: 10 | O17: =IF(ISNUMBER(SEARCH('Data Entry'!$J$3,$Q17)),MAX($O$1:$O16)+1,0) -> 0 | P17: =IF(ISNUMBER(SEARCH('Data Entry'!$J$3,$Q17)),MAX($P$1:$P16)+1,0) -> 0 | Q17: =Table2[[#This Row],[Item Name ]] -> Big Peanuts (original) | R17: =IFERROR(VLOOKUP(ROWS($R$2:$R17),Table2[[Nub2]:[Name]],2,0),"") | W17: =IF(ISNUMBER(SEARCH('Data Entry'!$J$3,$Y17)),MAX($W$1:$W16)+1,0) -> 0 | X17: =IF(ISNUMBER(SEARCH('Data Entry'!$J$3,$Y17)),MAX($X$1:$X16)+1,0) -> 0 | Y17: AEON MALL (CAMBODIA) CO., LTD_A3 | Z17: =IFERROR(VLOOKUP(ROWS($Z$2:$Z17),Table4[[Nub2]:[Supplied Name]],2,0),"") | AA17: =OFFSET($Z$2,,,COUNTIF($Z$2:$Z$25,"?*")) -> #REF! | AC17: =IF(ISNUMBER(SEARCH('Data Entry'!$J$3,$AE17)),MAX($AC$1:$AC16)+1,0) -> 0 | AD17: =IF(ISNUMBER(SEARCH('Data Entry'!$J$3,$AE17)),MAX($AD$1:$AD16)+1,0) -> 0 | AE17: Office & Admin | AF17: =IFERROR(VLOOKUP(ROWS($Z$2:$Z17),Table5[[#All],[Nub2]:[Location ]],2,0),"") | AG17: =OFFSET($AF$2,,,COUNTIF($AF$2:$AF$25,"?*")) -> #REF!
A18: {=ROW(17:17)} -> 17 | B18: DF-0015 | C18: 900150 | D18: Big Peanuts (spicy) | F18: CENTRAL KITCHEN | G18: FOOD | H18: Dry Food | I18: PKT | J18: 1PKT*150G | K18: 0.76 | M18: 1 | N18: 10 | O18: =IF(ISNUMBER(SEARCH('Data Entry'!$J$3,$Q18)),MAX($O$1:$O17)+1,0) -> 0 | P18: =IF(ISNUMBER(SEARCH('Data Entry'!$J$3,$Q18)),MAX($P$1:$P17)+1,0) -> 0 | Q18: =Table2[[#This Row],[Item Name ]] -> Big Peanuts (spicy) | R18: =IFERROR(VLOOKUP(ROWS($R$2:$R18),Table2[[Nub2]:[Name]],2,0),"") | W18: =IF(ISNUMBER(SEARCH('Data Entry'!$J$3,$Y18)),MAX($W$1:$W17)+1,0) -> 0 | X18: =IF(ISNUMBER(SEARCH('Data Entry'!$J$3,$Y18)),MAX($X$1:$X17)+1,0) -> 0 | Y18: AEON Mall (Cambodia) Co., Ltd | Z18: =IFERROR(VLOOKUP(ROWS($Z$2:$Z18),Table4[[Nub2]:[Supplied Name]],2,0),"") | AA18: =OFFSET($Z$2,,,COUNTIF($Z$2:$Z$25,"?*")) -> #REF! | AC18: =IF(ISNUMBER(SEARCH('Data Entry'!$J$3,$AE18)),MAX($AC$1:$AC17)+1,0) -> 0 | AD18: =IF(ISNUMBER(SEARCH('Data Entry'!$J$3,$AE18)),MAX($AD$1:$AD17)+1,0) -> 0 | AE18: QB - 271 Mega Mall | AF18: =IFERROR(VLOOKUP(ROWS($Z$2:$Z18),Table5[[#All],[Nub2]:[Location ]],2,0),"") | AG18: =OFFSET($AF$2,,,COUNTIF($AF$2:$AF$25,"?*")) -> #REF!
A19: {=ROW(18:18)} -> 18 | B19: FF-0001 | C19: 900281 | D19: Fresh Honey Melon In The Cup | F19: CENTRAL KITCHEN | G19: FOOD | H19: Fresh Fruit | I19: Cup | K19: 1.356 | M19: 1 | N19: 10 | O19: =IF(ISNUMBER(SEARCH('Data Entry'!$J$3,$Q19)),MAX($O$1:$O18)+1,0) -> 0 | P19: =IF(ISNUMBER(SEARCH('Data Entry'!$J$3,$Q19)),MAX($P$1:$P18)+1,0) -> 0 | Q19: =Table2[[#This Row],[Item Name ]] -> Fresh Honey Melon In The Cup | R19: =IFERROR(VLOOKUP(ROWS($R$2:$R19),Table2[[Nub2]:[Name]],2,0),"") | W19: =IF(ISNUMBER(SEARCH('Data Entry'!$J$3,$Y19)),MAX($W$1:$W18)+1,0) -> 0 | X19: =IF(ISNUMBER(SEARCH('Data Entry'!$J$3,$Y19)),MAX($X$1:$X18)+1,0) -> 0 | Y19: AGB Consulting Co.,Ltd | Z19: =IFERROR(VLOOKUP(ROWS($Z$2:$Z19),Table4[[Nub2]:[Supplied Name]],2,0),"") | AA19: =OFFSET($Z$2,,,COUNTIF($Z$2:$Z$25,"?*")) -> #REF! | AC19: =IF(ISNUMBER(SEARCH('Data Entry'!$J$3,$AE19)),MAX($AC$1:$AC18)+1,0) -> 0 | AD19: =IF(ISNUMBER(SEARCH('Data Entry'!$J$3,$AE19)),MAX($AD$1:$AD18)+1,0) -> 0 | AE19: QB PPIU | AF19: =IFERROR(VLOOKUP(ROWS($Z$2:$Z19),Table5[[#All],[Nub2]:[Location ]],2,0),"") | AG19: =OFFSET($AF$2,,,COUNTIF($AF$2:$AF$25,"?*")) -> #REF!
A20: {=ROW(19:19)} -> 19 | B20: FF-0002 | C20: 900282 | D20: Fresh Red Apple In The Cup | F20: CENTRAL KITCHEN | G20: FOOD | H20: Fresh Fruit | I20: Cup | K20: 0.708 | M20: 1 | N20: 10 | O20: =IF(ISNUMBER(SEARCH('Data Entry'!$J$3,$Q20)),MAX($O$1:$O19)+1,0) -> 0 | P20: =IF(ISNUMBER(SEARCH('Data Entry'!$J$3,$Q20)),MAX($P$1:$P19)+1,0) -> 0 | Q20: =Table2[[#This Row],[Item Name ]] -> Fresh Red Apple In The Cup | R20: =IFERROR(VLOOKUP(ROWS($R$2:$R20),Table2[[Nub2]:[Name]],2,0),"") | W20: =IF(ISNUMBER(SEARCH('Data Entry'!$J$3,$Y20)),MAX($W$1:$W19)+1,0) -> 0 | X20: =IF(ISNUMBER(SEARCH('Data Entry'!$J$3,$Y20)),MAX($X$1:$X19)+1,0) -> 0 | Y20: AH VY Orusey Market | Z20: =IFERROR(VLOOKUP(ROWS($Z$2:$Z20),Table4[[Nub2]:[Supplied Name]],2,0),"") | AA20: =OFFSET($Z$2,,,COUNTIF($Z$2:$Z$25,"?*")) -> #REF! | AC20: =IF(ISNUMBER(SEARCH('Data Entry'!$J$3,$AE20)),MAX($AC$1:$AC19)+1,0) -> 0 | AD20: =IF(ISNUMBER(SEARCH('Data Entry'!$J$3,$AE20)),MAX($AD$1:$AD19)+1,0) -> 0 | AE20: QB-Aeon Meanchey | AF20: =IFERROR(VLOOKUP(ROWS($Z$2:$Z20),Table5[[#All],[Nub2]:[Location ]],2,0),"") | AG20: =OFFSET($AF$2,,,COUNTIF($AF$2:$AF$25,"?*")) -> #REF!
A21: {=ROW(20:20)} -> 20 | B21: FF-0003 | C21: 900283 | D21: Fresh Ripe Mango In The Cup | F21: CENTRAL KITCHEN | G21: FOOD | H21: Fresh Fruit | I21: Cup | K21: 0.66 | M21: 1 | N21: 10 | O21: =IF(ISNUMBER(SEARCH('Data Entry'!$J$3,$Q21)),MAX($O$1:$O20)+1,0) -> 0 | P21: =IF(ISNUMBER(SEARCH('Data Entry'!$J$3,$Q21)),MAX($P$1:$P20)+1,0) -> 0 | Q21: =Table2[[#This Row],[Item Name ]] -> Fresh Ripe Mango In The Cup | R21: =IFERROR(VLOOKUP(ROWS($R$2:$R21),Table2[[Nub2]:[Name]],2,0),"") | W21: =IF(ISNUMBER(SEARCH('Data Entry'!$J$3,$Y21)),MAX($W$1:$W20)+1,0) -> 0 | X21: =IF(ISNUMBER(SEARCH('Data Entry'!$J$3,$Y21)),MAX($X$1:$X20)+1,0) -> 0 | Y21: ANANA COMPUTER CO., LTD | Z21: =IFERROR(VLOOKUP(ROWS($Z$2:$Z21),Table4[[Nub2]:[Supplied Name]],2,0),"") | AA21: =OFFSET($Z$2,,,COUNTIF($Z$2:$Z$25,"?*")) -> #REF! | AC21: =IF(ISNUMBER(SEARCH('Data Entry'!$J$3,$AE21)),MAX($AC$1:$AC20)+1,0) -> 0 | AD21: =IF(ISNUMBER(SEARCH('Data Entry'!$J$3,$AE21)),MAX($AD$1:$AD20)+1,0) -> 0 | AE21: Tako Lounge- Toulkok | AF21: =IFERROR(VLOOKUP(ROWS($Z$2:$Z21),Table5[[#All],[Nub2]:[Location ]],2,0),"") | AG21: =OFFSET($AF$2,,,COUNTIF($AF$2:$AF$25,"?*")) -> #REF!
A22: {=ROW(21:21)} -> 21 | B22: FF-0004 | C22: 900284 | D22: Fresh Ripe watermelon In The Cup | F22: CENTRAL KITCHEN | G22: FOOD | H22: Fresh Fruit | I22: Cup | K22: 0.504 | M22: 1 | N22: 10 | O22: =IF(ISNUMBER(SEARCH('Data Entry'!$J$3,$Q22)),MAX($O$1:$O21)+1,0) -> 0 | P22: =IF(ISNUMBER(SEARCH('Data Entry'!$J$3,$Q22)),MAX($P$1:$P21)+1,0) -> 0 | Q22: =Table2[[#This Row],[Item Name ]] -> Fresh Ripe watermelon In The Cup | R22: =IFERROR(VLOOKUP(ROWS($R$2:$R22),Table2[[Nub2]:[Name]],2,0),"") | W22: =IF(ISNUMBER(SEARCH('Data Entry'!$J$3,$Y22)),MAX($W$1:$W21)+1,0) -> 0 | X22: =IF(ISNUMBER(SEARCH('Data Entry'!$J$3,$Y22)),MAX($X$1:$X21)+1,0) -> 0 | Y22: ANTICIMEX PEST MANAGEMENT CO.,LTD | Z22: =IFERROR(VLOOKUP(ROWS($Z$2:$Z22),Table4[[Nub2]:[Supplied Name]],2,0),"") | AA22: =OFFSET($Z$2,,,COUNTIF($Z$2:$Z$25,"?*")) -> #REF! | AC22: =IF(ISNUMBER(SEARCH('Data Entry'!$J$3,$AE22)),MAX($AC$1:$AC21)+1,0) -> 0 | AD22: =IF(ISNUMBER(SEARCH('Data Entry'!$J$3,$AE22)),MAX($AD$1:$AD21)+1,0) -> 0 | AE22: The Cut - Boeung Kak | AF22: =IFERROR(VLOOKUP(ROWS($Z$2:$Z22),Table5[[#All],[Nub2]:[Location ]],2,0),"") | AG22: =OFFSET($AF$2,,,COUNTIF($AF$2:$AF$25,"?*")) -> #REF!
A23: {=ROW(22:22)} -> 22 | B23: FF-0005 | C23: 900285 | D23: Fresh Pineapple In The Cup | F23: CENTRAL KITCHEN | G23: FOOD | H23: Fresh Fruit | I23: Cup | K23: 0.396 | M23: 1 | N23: 10 | O23: =IF(ISNUMBER(SEARCH('Data Entry'!$J$3,$Q23)),MAX($O$1:$O22)+1,0) -> 0 | P23: =IF(ISNUMBER(SEARCH('Data Entry'!$J$3,$Q23)),MAX($P$1:$P22)+1,0) -> 0 | Q23: =Table2[[#This Row],[Item Name ]] -> Fresh Pineapple In The Cup | R23: =IFERROR(VLOOKUP(ROWS($R$2:$R23),Table2[[Nub2]:[Name]],2,0),"") | W23: =IF(ISNUMBER(SEARCH('Data Entry'!$J$3,$Y23)),MAX($W$1:$W22)+1,0) -> 0 | X23: =IF(ISNUMBER(SEARCH('Data Entry'!$J$3,$Y23)),MAX($X$1:$X22)+1,0) -> 0 | Y23: APOLLO ELOGISTICS CO., LTD | Z23: =IFERROR(VLOOKUP(ROWS($Z$2:$Z23),Table4[[Nub2]:[Supplied Name]],2,0),"") | AA23: =OFFSET($Z$2,,,COUNTIF($Z$2:$Z$25,"?*")) -> #REF! | AC23: =IF(ISNUMBER(SEARCH('Data Entry'!$J$3,$AE23)),MAX($AC$1:$AC22)+1,0) -> 0 | AD23: =IF(ISNUMBER(SEARCH('Data Entry'!$J$3,$AE23)),MAX($AD$1:$AD22)+1,0) -> 0 | AF23: =IFERROR(VLOOKUP(ROWS($Z$2:$Z23),Table5[[#All],[Nub2]:[Location ]],2,0),"") | AG23: =OFFSET($AF$2,,,COUNTIF($AF$2:$AF$25,"?*")) -> #REF!
A24: {=ROW(23:23)} -> 23 | B24: HF-0001 | C24: 900029 | D24: BEEF LOK LAK WITH RICE (បាយ​ ឡុកឡាក់សាច់គោ) | F24: CENTRAL KITCHEN | G24: FOOD | H24: Khmer Food | I24: BOX | J24: 1BOX*1Portion | K24: 1.668 | M24: 1 | N24: 10 | O24: =IF(ISNUMBER(SEARCH('Data Entry'!$J$3,$Q24)),MAX($O$1:$O23)+1,0) -> 0 | P24: =IF(ISNUMBER(SEARCH('Data Entry'!$J$3,$Q24)),MAX($P$1:$P23)+1,0) -> 0 | Q24: =Table2[[#This Row],[Item Name ]] -> BEEF LOK LAK WITH RICE (បាយ​ ឡុកឡាក់សាច់គោ) | R24: =IFERROR(VLOOKUP(ROWS($R$2:$R24),Table2[[Nub2]:[Name]],2,0),"") | W24: =IF(ISNUMBER(SEARCH('Data Entry'!$J$3,$Y24)),MAX($W$1:$W23)+1,0) -> 0 | X24: =IF(ISNUMBER(SEARCH('Data Entry'!$J$3,$Y24)),MAX($X$1:$X23)+1,0) -> 0 | Y24: ASIAN T A C T CO., LTD | Z24: =IFERROR(VLOOKUP(ROWS($Z$2:$Z24),Table4[[Nub2]:[Supplied Name]],2,0),"") | AA24: =OFFSET($Z$2,,,COUNTIF($Z$2:$Z$25,"?*")) -> #REF! | AC24: =IF(ISNUMBER(SEARCH('Data Entry'!$J$3,$AE24)),MAX($AC$1:$AC23)+1,0) -> 0 | AD24: =IF(ISNUMBER(SEARCH('Data Entry'!$J$3,$AE24)),MAX($AD$1:$AD23)+1,0) -> 0 | AF24: =IFERROR(VLOOKUP(ROWS($Z$2:$Z24),Table5[[#All],[Nub2]:[Location ]],2,0),"") | AG24: =OFFSET($AF$2,,,COUNTIF($AF$2:$AF$25,"?*")) -> #REF!
A25: {=ROW(24:24)} -> 24 | B25: HF-0002 | C25: 900027 | D25: STIR FRIED MINCED PORK HOT BASIL WITH RICE (បាយ សាច់ជ្រូកចិញ្រ្ចាំឆាម្រះព្រៅ) | F25: CENTRAL KITCHEN | G25: FOOD | H25: Khmer Food | I25: BOX | J25: 1BOX*1Portion | K25: 1.2024 | M25: 1 | N25: 10 | O25: =IF(ISNUMBER(SEARCH('Data Entry'!$J$3,$Q25)),MAX($O$1:$O24)+1,0) -> 0 | P25: =IF(ISNUMBER(SEARCH('Data Entry'!$J$3,$Q25)),MAX($P$1:$P24)+1,0) -> 0 | Q25: =Table2[[#This Row],[Item Name ]] -> STIR FRIED MINCED PORK HOT BASIL WITH RICE (បាយ សាច់ជ្រូកចិញ្រ្ចាំឆាម្រះព្រៅ) | R25: =IFERROR(VLOOKUP(ROWS($R$2:$R25),Table2[[Nub2]:[Name]],2,0),"") | W25: =IF(ISNUMBER(SEARCH('Data Entry'!$J$3,$Y25)),MAX($W$1:$W24)+1,0) -> 0 | X25: =IF(ISNUMBER(SEARCH('Data Entry'!$J$3,$Y25)),MAX($X$1:$X24)+1,0) -> 0 | Y25: AT & B CONSTRUCTING | Z25: =IFERROR(VLOOKUP(ROWS($Z$2:$Z25),Table4[[Nub2]:[Supplied Name]],2,0),"") | AA25: =OFFSET($Z$2,,,COUNTIF($Z$2:$Z$25,"?*")) -> #REF! | AC25: =IF(ISNUMBER(SEARCH('Data Entry'!$J$3,$AE25)),MAX($AC$1:$AC24)+1,0) -> 0 | AD25: =IF(ISNUMBER(SEARCH('Data Entry'!$J$3,$AE25)),MAX($AD$1:$AD24)+1,0) -> 0 | AF25: =IFERROR(VLOOKUP(ROWS($Z$2:$Z25),Table5[[#All],[Nub2]:[Location ]],2,0),"") | AG25: =OFFSET($AF$2,,,COUNTIF($AF$2:$AF$25,"?*")) -> #REF!
A26: {=ROW(25:25)} -> 25 | B26: HF-0003 | C26: 900026 | D26: STIR FRIED CHICKEN HOT BASIL WITH RICE (បាយ​ សាច់មាន់ឆាក្ដៅ) | F26: CENTRAL KITCHEN | G26: FOOD | H26: Khmer Food | I26: BOX | J26: 1BOX*1Portion | K26: 1.2984 | M26: 1 | N26: 10 | O26: =IF(ISNUMBER(SEARCH('Data Entry'!$J$3,$Q26)),MAX($O$1:$O25)+1,0) -> 0 | P26: =IF(ISNUMBER(SEARCH('Data Entry'!$J$3,$Q26)),MAX($P$1:$P25)+1,0) -> 0 | Q26: =Table2[[#This Row],[Item Name ]] -> STIR FRIED CHICKEN HOT BASIL WITH RICE (បាយ​ សាច់មាន់ឆាក្ដៅ) | R26: =IFERROR(VLOOKUP(ROWS($R$2:$R26),Table2[[Nub2]:[Name]],2,0),"") | W26: =IF(ISNUMBER(SEARCH('Data Entry'!$J$3,$Y26)),MAX($W$1:$W25)+1,0) -> 0 | X26: =IF(ISNUMBER(SEARCH('Data Entry'!$J$3,$Y26)),MAX($X$1:$X25)+1,0) -> 0 | Y26: ATLAS ICE (Cambodia) Co., Ltd | Z26: =IFERROR(VLOOKUP(ROWS($Z$2:$Z26),Table4[[Nub2]:[Supplied Name]],2,0),"") | AA26: =OFFSET($Z$2,,,COUNTIF($Z$2:$Z$25,"?*")) -> #REF! | AC26: =IF(ISNUMBER(SEARCH('Data Entry'!$J$3,$AE26)),MAX($AC$1:$AC25)+1,0) -> 0 | AD26: =IF(ISNUMBER(SEARCH('Data Entry'!$J$3,$AE26)),MAX($AD$1:$AD25)+1,0) -> 0 | AF26: =IFERROR(VLOOKUP(ROWS($Z$2:$Z26),Table5[[#All],[Nub2]:[Location ]],2,0),"") | AG26: =OFFSET($AF$2,,,COUNTIF($AF$2:$AF$25,"?*")) -> #REF!
A27: {=ROW(26:26)} -> 26 | B27: HF-0004 | C27: 900032 | D27: STIR FRIED MINCED CHICKEN HOT BASIL WITH RICE (បាយ​ សាច់មាន់ចិញ្រ្ចាំឆាម្រះព្រៅ) | F27: CENTRAL KITCHEN | G27: FOOD | H27: Khmer Food | I27: BOX | J27: 1BOX*1Portion | K27: 1.2984 | M27: 1 | N27: 10 | O27: =IF(ISNUMBER(SEARCH('Data Entry'!$J$3,$Q27)),MAX($O$1:$O26)+1,0) -> 0 | P27: =IF(ISNUMBER(SEARCH('Data Entry'!$J$3,$Q27)),MAX($P$1:$P26)+1,0) -> 0 | Q27: =Table2[[#This Row],[Item Name ]] -> STIR FRIED MINCED CHICKEN HOT BASIL WITH RICE (បាយ​ សាច់មាន់ចិញ្រ្ចាំឆាម្រះព្រៅ) | R27: =IFERROR(VLOOKUP(ROWS($R$2:$R27),Table2[[Nub2]:[Name]],2,0),"") | W27: =IF(ISNUMBER(SEARCH('Data Entry'!$J$3,$Y27)),MAX($W$1:$W26)+1,0) -> 0 | X27: =IF(ISNUMBER(SEARCH('Data Entry'!$J$3,$Y27)),MAX($X$1:$X26)+1,0) -> 0 | Y27: ATTWOOD IMPORT EXPORT CO., LTD | Z27: =IFERROR(VLOOKUP(ROWS($Z$2:$Z27),Table4[[Nub2]:[Supplied Name]],2,0),"") | AA27: =OFFSET($Z$2,,,COUNTIF($Z$2:$Z$25,"?*")) -> #REF! | AC27: =IF(ISNUMBER(SEARCH('Data Entry'!$J$3,$AE27)),MAX($AC$1:$AC26)+1,0) -> 0 | AD27: =IF(ISNUMBER(SEARCH('Data Entry'!$J$3,$AE27)),MAX($AD$1:$AD26)+1,0) -> 0 | AF27: =IFERROR(VLOOKUP(ROWS($Z$2:$Z27),Table5[[#All],[Nub2]:[Location ]],2,0),"") | AG27: =OFFSET($AF$2,,,COUNTIF($AF$2:$AF$25,"?*")) -> #REF!
A28: {=ROW(27:27)} -> 27 | B28: HF-0005 | C28: 900028 | D28: STIR FRIED MINCED PORK EGGPLANT WITH RICE (បាយ សាច់ជ្រូកចិញ្ច្រាំឆាត្រប់វែង) | F28: CENTRAL KITCHEN | G28: FOOD | H28: Khmer Food | I28: BOX | J28: 1BOX*1Portion | K28: 1.0104 | M28: 1 | N28: 10 | O28: =IF(ISNUMBER(SEARCH('Data Entry'!$J$3,$Q28)),MAX($O$1:$O27)+1,0) -> 0 | P28: =IF(ISNUMBER(SEARCH('Data Entry'!$J$3,$Q28)),MAX($P$1:$P27)+1,0) -> 0 | Q28: =Table2[[#This Row],[Item Name ]] -> STIR FRIED MINCED PORK EGGPLANT WITH RICE (បាយ សាច់ជ្រូកចិញ្ច្រាំឆាត្រប់វែង) | R28: =IFERROR(VLOOKUP(ROWS($R$2:$R28),Table2[[Nub2]:[Name]],2,0),"") | W28: =IF(ISNUMBER(SEARCH('Data Entry'!$J$3,$Y28)),MAX($W$1:$W27)+1,0) -> 0 | X28: =IF(ISNUMBER(SEARCH('Data Entry'!$J$3,$Y28)),MAX($X$1:$X27)+1,0) -> 0 | Y28: AUS KHMER IMPORT EXPORT CO.,LTD | Z28: =IFERROR(VLOOKUP(ROWS($Z$2:$Z28),Table4[[Nub2]:[Supplied Name]],2,0),"") | AA28: =OFFSET($Z$2,,,COUNTIF($Z$2:$Z$25,"?*")) -> #REF! | AC28: =IF(ISNUMBER(SEARCH('Data Entry'!$J$3,$AE28)),MAX($AC$1:$AC27)+1,0) -> 0 | AD28: =IF(ISNUMBER(SEARCH('Data Entry'!$J$3,$AE28)),MAX($AD$1:$AD27)+1,0) -> 0 | AF28: =IFERROR(VLOOKUP(ROWS($Z$2:$Z28),Table5[[#All],[Nub2]:[Location ]],2,0),"") | AG28: =OFFSET($AF$2,,,COUNTIF($AF$2:$AF$25,"?*")) -> #REF!
A29: {=ROW(28:28)} -> 28 | B29: HF-0006 | C29: 900025 | D29: HAINANESE CHICKEN WITH RICE (បាយ មាន់ហៃណាំ) | F29: CENTRAL KITCHEN | G29: FOOD | H29: Khmer Food | I29: BOX | J29: 1BOX*1Portion | K29: 1.0584 | M29: 1 | N29: 10 | O29: =IF(ISNUMBER(SEARCH('Data Entry'!$J$3,$Q29)),MAX($O$1:$O28)+1,0) -> 0 | P29: =IF(ISNUMBER(SEARCH('Data Entry'!$J$3,$Q29)),MAX($P$1:$P28)+1,0) -> 0 | Q29: =Table2[[#This Row],[Item Name ]] -> HAINANESE CHICKEN WITH RICE (បាយ មាន់ហៃណាំ) | R29: =IFERROR(VLOOKUP(ROWS($R$2:$R29),Table2[[Nub2]:[Name]],2,0),"") | W29: =IF(ISNUMBER(SEARCH('Data Entry'!$J$3,$Y29)),MAX($W$1:$W28)+1,0) -> 0 | X29: =IF(ISNUMBER(SEARCH('Data Entry'!$J$3,$Y29)),MAX($X$1:$X28)+1,0) -> 0 | Y29: AXION Printing & Supplies Material | Z29: =IFERROR(VLOOKUP(ROWS($Z$2:$Z29),Table4[[Nub2]:[Supplied Name]],2,0),"") | AA29: =OFFSET($Z$2,,,COUNTIF($Z$2:$Z$25,"?*")) -> #REF! | AC29: =IF(ISNUMBER(SEARCH('Data Entry'!$J$3,$AE29)),MAX($AC$1:$AC28)+1,0) -> 0 | AD29: =IF(ISNUMBER(SEARCH('Data Entry'!$J$3,$AE29)),MAX($AD$1:$AD28)+1,0) -> 0 | AF29: =IFERROR(VLOOKUP(ROWS($Z$2:$Z29),Table5[[#All],[Nub2]:[Location ]],2,0),"") | AG29: =OFFSET($AF$2,,,COUNTIF($AF$2:$AF$25,"?*")) -> #REF!
A30: {=ROW(29:29)} -> 29 | B30: HF-0007 | C30: 900030 | D30: ROASTED CHICKEN WITH RICE (បាយ មាន់ខ្វៃ) | F30: CENTRAL KITCHEN | G30: FOOD | H30: Khmer Food | I30: BOX | J30: 1BOX*1Portion | K30: 1.07 | M30: 1 | N30: 10 | O30: =IF(ISNUMBER(SEARCH('Data Entry'!$J$3,$Q30)),MAX($O$1:$O29)+1,0) -> 0 | P30: =IF(ISNUMBER(SEARCH('Data Entry'!$J$3,$Q30)),MAX($P$1:$P29)+1,0) -> 0 | Q30: =Table2[[#This Row],[Item Name ]] -> ROASTED CHICKEN WITH RICE (បាយ មាន់ខ្វៃ) | R30: =IFERROR(VLOOKUP(ROWS($R$2:$R30),Table2[[Nub2]:[Name]],2,0),"") | W30: =IF(ISNUMBER(SEARCH('Data Entry'!$J$3,$Y30)),MAX($W$1:$W29)+1,0) -> 0 | X30: =IF(ISNUMBER(SEARCH('Data Entry'!$J$3,$Y30)),MAX($X$1:$X29)+1,0) -> 0 | Y30: Adalloon Balloon and Party Supplies | Z30: =IFERROR(VLOOKUP(ROWS($Z$2:$Z30),Table4[[Nub2]:[Supplied Name]],2,0),"") | AA30: =OFFSET($Z$2,,,COUNTIF($Z$2:$Z$25,"?*")) -> #REF! | AC30: =IF(ISNUMBER(SEARCH('Data Entry'!$J$3,$AE30)),MAX($AC$1:$AC29)+1,0) -> 0 | AD30: =IF(ISNUMBER(SEARCH('Data Entry'!$J$3,$AE30)),MAX($AD$1:$AD29)+1,0) -> 0 | AF30: =IFERROR(VLOOKUP(ROWS($Z$2:$Z30),Table5[[#All],[Nub2]:[Location ]],2,0),"") | AG30: =OFFSET($AF$2,,,COUNTIF($AF$2:$AF$25,"?*")) -> #REF!
A31: {=ROW(30:30)} -> 30 | B31: HF-0008 | C31: 900031 | D31: ROASTED DUCK WITH RICE (បាយ ទាខ្វៃ) | F31: CENTRAL KITCHEN | G31: FOOD | H31: Khmer Food | I31: BOX | J31: 1BOX*1Portion | K31: 1.4784 | M31: 1 | N31: 10 | O31: =IF(ISNUMBER(SEARCH('Data Entry'!$J$3,$Q31)),MAX($O$1:$O30)+1,0) -> 0 | P31: =IF(ISNUMBER(SEARCH('Data Entry'!$J$3,$Q31)),MAX($P$1:$P30)+1,0) -> 0 | Q31: =Table2[[#This Row],[Item Name ]] -> ROASTED DUCK WITH RICE (បាយ ទាខ្វៃ) | R31: =IFERROR(VLOOKUP(ROWS($R$2:$R31),Table2[[Nub2]:[Name]],2,0),"") | W31: =IF(ISNUMBER(SEARCH('Data Entry'!$J$3,$Y31)),MAX($W$1:$W30)+1,0) -> 0 | X31: =IF(ISNUMBER(SEARCH('Data Entry'!$J$3,$Y31)),MAX($X$1:$X30)+1,0) -> 0 | Y31: Alphapeak Co., Ltd | Z31: =IFERROR(VLOOKUP(ROWS($Z$2:$Z31),Table4[[Nub2]:[Supplied Name]],2,0),"") | AA31: =OFFSET($Z$2,,,COUNTIF($Z$2:$Z$25,"?*")) -> #REF! | AC31: =IF(ISNUMBER(SEARCH('Data Entry'!$J$3,$AE31)),MAX($AC$1:$AC30)+1,0) -> 0 | AD31: =IF(ISNUMBER(SEARCH('Data Entry'!$J$3,$AE31)),MAX($AD$1:$AD30)+1,0) -> 0 | AF31: =IFERROR(VLOOKUP(ROWS($Z$2:$Z31),Table5[[#All],[Nub2]:[Location ]],2,0),"") | AG31: =OFFSET($AF$2,,,COUNTIF($AF$2:$AF$25,"?*")) -> #REF!
A32: {=ROW(31:31)} -> 31 | B32: HF-0009 | C32: 900286 | D32: ROATED PORK CHAR SIEW WITH RICE (បាយ សាច់ជ្រូកសាស៊ីវ) | F32: CENTRAL KITCHEN | G32: FOOD | H32: Khmer Food | I32: BOX | J32: 1BOX*1Portion | K32: 1.476 | M32: 1 | N32: 10 | O32: =IF(ISNUMBER(SEARCH('Data Entry'!$J$3,$Q32)),MAX($O$1:$O31)+1,0) -> 0 | P32: =IF(ISNUMBER(SEARCH('Data Entry'!$J$3,$Q32)),MAX($P$1:$P31)+1,0) -> 0 | Q32: =Table2[[#This Row],[Item Name ]] -> ROATED PORK CHAR SIEW WITH RICE (បាយ សាច់ជ្រូកសាស៊ីវ) | R32: =IFERROR(VLOOKUP(ROWS($R$2:$R32),Table2[[Nub2]:[Name]],2,0),"") | W32: =IF(ISNUMBER(SEARCH('Data Entry'!$J$3,$Y32)),MAX($W$1:$W31)+1,0) -> 0 | X32: =IF(ISNUMBER(SEARCH('Data Entry'!$J$3,$Y32)),MAX($X$1:$X31)+1,0) -> 0 | Y32: American Chamberof Commerce in Cambodia | Z32: =IFERROR(VLOOKUP(ROWS($Z$2:$Z32),Table4[[Nub2]:[Supplied Name]],2,0),"") | AA32: =OFFSET($Z$2,,,COUNTIF($Z$2:$Z$25,"?*")) -> #REF! | AC32: =IF(ISNUMBER(SEARCH('Data Entry'!$J$3,$AE32)),MAX($AC$1:$AC31)+1,0) -> 0 | AD32: =IF(ISNUMBER(SEARCH('Data Entry'!$J$3,$AE32)),MAX($AD$1:$AD31)+1,0) -> 0 | AF32: =IFERROR(VLOOKUP(ROWS($Z$2:$Z32),Table5[[#All],[Nub2]:[Location ]],2,0),"") | AG32: =OFFSET($AF$2,,,COUNTIF($AF$2:$AF$25,"?*")) -> #REF!
A33: {=ROW(32:32)} -> 32 | B33: HF-0010 | C33: 900038 | D33: ROATED PORK BELLY WITH RICE (បាយ សាច់ជ្រូក៣ជាន់) | F33: CENTRAL KITCHEN | G33: FOOD | H33: Khmer Food | I33: BOX | J33: 1BOX*1Portion | K33: 1.092 | M33: 1 | N33: 10 | O33: =IF(ISNUMBER(SEARCH('Data Entry'!$J$3,$Q33)),MAX($O$1:$O32)+1,0) -> 0 | P33: =IF(ISNUMBER(SEARCH('Data Entry'!$J$3,$Q33)),MAX($P$1:$P32)+1,0) -> 0 | Q33: =Table2[[#This Row],[Item Name ]] -> ROATED PORK BELLY WITH RICE (បាយ សាច់ជ្រូក៣ជាន់) | R33: =IFERROR(VLOOKUP(ROWS($R$2:$R33),Table2[[Nub2]:[Name]],2,0),"") | W33: =IF(ISNUMBER(SEARCH('Data Entry'!$J$3,$Y33)),MAX($W$1:$W32)+1,0) -> 0 | X33: =IF(ISNUMBER(SEARCH('Data Entry'!$J$3,$Y33)),MAX($X$1:$X32)+1,0) -> 0 | Y33: Angkor Art Printing House | Z33: =IFERROR(VLOOKUP(ROWS($Z$2:$Z33),Table4[[Nub2]:[Supplied Name]],2,0),"") | AA33: =OFFSET($Z$2,,,COUNTIF($Z$2:$Z$25,"?*")) -> #REF! | AC33: =IF(ISNUMBER(SEARCH('Data Entry'!$J$3,$AE33)),MAX($AC$1:$AC32)+1,0) -> 0 | AD33: =IF(ISNUMBER(SEARCH('Data Entry'!$J$3,$AE33)),MAX($AD$1:$AD32)+1,0) -> 0 | AF33: =IFERROR(VLOOKUP(ROWS($Z$2:$Z33),Table5[[#All],[Nub2]:[Location ]],2,0),"") | AG33: =OFFSET($AF$2,,,COUNTIF($AF$2:$AF$25,"?*")) -> #REF!
A34: {=ROW(33:33)} -> 33 | B34: HF-0011 | C34: 900036 | D34: THICK CHICKEN CURRY (ការីសាច់មាន់) ខាប់ | F34: CENTRAL KITCHEN | G34: FOOD | H34: Khmer Food | I34: BOX | J34: 1BOX*1Portion | K34: 1.3824 | M34: 1 | N34: 10 | O34: =IF(ISNUMBER(SEARCH('Data Entry'!$J$3,$Q34)),MAX($O$1:$O33)+1,0) -> 0 | P34: =IF(ISNUMBER(SEARCH('Data Entry'!$J$3,$Q34)),MAX($P$1:$P33)+1,0) -> 0 | Q34: =Table2[[#This Row],[Item Name ]] -> THICK CHICKEN CURRY (ការីសាច់មាន់) ខាប់ | R34: =IFERROR(VLOOKUP(ROWS($R$2:$R34),Table2[[Nub2]:[Name]],2,0),"") | W34: =IF(ISNUMBER(SEARCH('Data Entry'!$J$3,$Y34)),MAX($W$1:$W33)+1,0) -> 0 | X34: =IF(ISNUMBER(SEARCH('Data Entry'!$J$3,$Y34)),MAX($X$1:$X33)+1,0) -> 0 | Y34: Angkor Shoes Making | Z34: =IFERROR(VLOOKUP(ROWS($Z$2:$Z34),Table4[[Nub2]:[Supplied Name]],2,0),"") | AA34: =OFFSET($Z$2,,,COUNTIF($Z$2:$Z$25,"?*")) -> #REF! | AC34: =IF(ISNUMBER(SEARCH('Data Entry'!$J$3,$AE34)),MAX($AC$1:$AC33)+1,0) -> 0 | AD34: =IF(ISNUMBER(SEARCH('Data Entry'!$J$3,$AE34)),MAX($AD$1:$AD33)+1,0) -> 0 | AF34: =IFERROR(VLOOKUP(ROWS($Z$2:$Z34),Table5[[#All],[Nub2]:[Location ]],2,0),"") | AG34: =OFFSET($AF$2,,,COUNTIF($AF$2:$AF$25,"?*")) -> #REF!
A35: {=ROW(34:34)} -> 34 | B35: HF-0012 | C35: 900035 | D35: THICK BEEF CURRY SARAMAN (ការីសារ៉ាម៉ាន់សាច់គោ) ខាប់ | F35: CENTRAL KITCHEN | G35: FOOD | H35: Khmer Food | I35: BOX | J35: 1BOX*1Portion | K35: 1.908 | M35: 1 | N35: 10 | O35: =IF(ISNUMBER(SEARCH('Data Entry'!$J$3,$Q35)),MAX($O$1:$O34)+1,0) -> 0 | P35: =IF(ISNUMBER(SEARCH('Data Entry'!$J$3,$Q35)),MAX($P$1:$P34)+1,0) -> 0 | Q35: =Table2[[#This Row],[Item Name ]] -> THICK BEEF CURRY SARAMAN (ការីសារ៉ាម៉ាន់សាច់គោ) ខាប់ | R35: =IFERROR(VLOOKUP(ROWS($R$2:$R35),Table2[[Nub2]:[Name]],2,0),"") | W35: =IF(ISNUMBER(SEARCH('Data Entry'!$J$3,$Y35)),MAX($W$1:$W34)+1,0) -> 0 | X35: =IF(ISNUMBER(SEARCH('Data Entry'!$J$3,$Y35)),MAX($X$1:$X34)+1,0) -> 0 | Y35: Anon Studio | Z35: =IFERROR(VLOOKUP(ROWS($Z$2:$Z35),Table4[[Nub2]:[Supplied Name]],2,0),"") | AA35: =OFFSET($Z$2,,,COUNTIF($Z$2:$Z$25,"?*")) -> #REF! | AC35: =IF(ISNUMBER(SEARCH('Data Entry'!$J$3,$AE35)),MAX($AC$1:$AC34)+1,0) -> 0 | AD35: =IF(ISNUMBER(SEARCH('Data Entry'!$J$3,$AE35)),MAX($AD$1:$AD34)+1,0) -> 0 | AF35: =IFERROR(VLOOKUP(ROWS($Z$2:$Z35),Table5[[#All],[Nub2]:[Location ]],2,0),"") | AG35: =OFFSET($AF$2,,,COUNTIF($AF$2:$AF$25,"?*")) -> #REF!
A36: {=ROW(35:35)} -> 35 | B36: HF-0016 | C36: 900033 | D36: GRILLED PORK WITH RICE (បាយ សាច់ជ្រូកអាំង) | F36: CENTRAL KITCHEN | G36: FOOD | H36: Khmer Food | I36: BOX | J36: 1BOX*1Portion | K36: 1.212 | M36: 1 | N36: 10 | O36: =IF(ISNUMBER(SEARCH('Data Entry'!$J$3,$Q36)),MAX($O$1:$O35)+1,0) -> 0 | P36: =IF(ISNUMBER(SEARCH('Data Entry'!$J$3,$Q36)),MAX($P$1:$P35)+1,0) -> 0 | Q36: =Table2[[#This Row],[Item Name ]] -> GRILLED PORK WITH RICE (បាយ សាច់ជ្រូកអាំង) | R36: =IFERROR(VLOOKUP(ROWS($R$2:$R36),Table2[[Nub2]:[Name]],2,0),"") | W36: =IF(ISNUMBER(SEARCH('Data Entry'!$J$3,$Y36)),MAX($W$1:$W35)+1,0) -> 0 | X36: =IF(ISNUMBER(SEARCH('Data Entry'!$J$3,$Y36)),MAX($X$1:$X35)+1,0) -> 0 | Y36: Anorng Interior Design | Z36: =IFERROR(VLOOKUP(ROWS($Z$2:$Z36),Table4[[Nub2]:[Supplied Name]],2,0),"") | AA36: =OFFSET($Z$2,,,COUNTIF($Z$2:$Z$25,"?*")) -> #REF! | AC36: =IF(ISNUMBER(SEARCH('Data Entry'!$J$3,$AE36)),MAX($AC$1:$AC35)+1,0) -> 0 | AD36: =IF(ISNUMBER(SEARCH('Data Entry'!$J$3,$AE36)),MAX($AD$1:$AD35)+1,0) -> 0 | AF36: =IFERROR(VLOOKUP(ROWS($Z$2:$Z36),Table5[[#All],[Nub2]:[Location ]],2,0),"") | AG36: =OFFSET($AF$2,,,COUNTIF($AF$2:$AF$25,"?*")) -> #REF!
A37: {=ROW(36:36)} -> 36 | B37: HF-0017 | C37: 900037 | D37: HIKO FRIED RICE (បាយឆា HIKO) | F37: CENTRAL KITCHEN | G37: FOOD | H37: Khmer Food | I37: BOX | J37: 1BOX*1Portion | K37: 1.68 | M37: 1 | N37: 10 | O37: =IF(ISNUMBER(SEARCH('Data Entry'!$J$3,$Q37)),MAX($O$1:$O36)+1,0) -> 0 | P37: =IF(ISNUMBER(SEARCH('Data Entry'!$J$3,$Q37)),MAX($P$1:$P36)+1,0) -> 0 | Q37: =Table2[[#This Row],[Item Name ]] -> HIKO FRIED RICE (បាយឆា HIKO) | R37: =IFERROR(VLOOKUP(ROWS($R$2:$R37),Table2[[Nub2]:[Name]],2,0),"") | W37: =IF(ISNUMBER(SEARCH('Data Entry'!$J$3,$Y37)),MAX($W$1:$W36)+1,0) -> 0 | X37: =IF(ISNUMBER(SEARCH('Data Entry'!$J$3,$Y37)),MAX($X$1:$X36)+1,0) -> 0 | Y37: Apsara Modern Furniture Shop | Z37: =IFERROR(VLOOKUP(ROWS($Z$2:$Z37),Table4[[Nub2]:[Supplied Name]],2,0),"") | AA37: =OFFSET($Z$2,,,COUNTIF($Z$2:$Z$25,"?*")) -> #REF! | AC37: =IF(ISNUMBER(SEARCH('Data Entry'!$J$3,$AE37)),MAX($AC$1:$AC36)+1,0) -> 0 | AD37: =IF(ISNUMBER(SEARCH('Data Entry'!$J$3,$AE37)),MAX($AD$1:$AD36)+1,0) -> 0 | AF37: =IFERROR(VLOOKUP(ROWS($Z$2:$Z37),Table5[[#All],[Nub2]:[Location ]],2,0),"") | AG37: =OFFSET($AF$2,,,COUNTIF($AF$2:$AF$25,"?*")) -> #REF!
A38: {=ROW(37:37)} -> 37 | B38: I-0001 | C38: 900268 | D38: White Sugar (Bag*50Kg) | F38: CENTRAL KITCHEN | G38: FOOD | H38: Ingredients | I38: KG | J38: 1BAG*50KG | K38: 0.96 | M38: 1 | N38: 10 | O38: =IF(ISNUMBER(SEARCH('Data Entry'!$J$3,$Q38)),MAX($O$1:$O37)+1,0) -> 0 | P38: =IF(ISNUMBER(SEARCH('Data Entry'!$J$3,$Q38)),MAX($P$1:$P37)+1,0) -> 0 | Q38: =Table2[[#This Row],[Item Name ]] -> White Sugar (Bag*50Kg) | R38: =IFERROR(VLOOKUP(ROWS($R$2:$R38),Table2[[Nub2]:[Name]],2,0),"") | W38: =IF(ISNUMBER(SEARCH('Data Entry'!$J$3,$Y38)),MAX($W$1:$W37)+1,0) -> 0 | X38: =IF(ISNUMBER(SEARCH('Data Entry'!$J$3,$Y38)),MAX($X$1:$X37)+1,0) -> 0 | Y38: Aqua Filter | Z38: =IFERROR(VLOOKUP(ROWS($Z$2:$Z38),Table4[[Nub2]:[Supplied Name]],2,0),"") | AA38: =OFFSET($Z$2,,,COUNTIF($Z$2:$Z$25,"?*")) -> #REF! | AC38: =IF(ISNUMBER(SEARCH('Data Entry'!$J$3,$AE38)),MAX($AC$1:$AC37)+1,0) -> 0 | AD38: =IF(ISNUMBER(SEARCH('Data Entry'!$J$3,$AE38)),MAX($AD$1:$AD37)+1,0) -> 0 | AF38: =IFERROR(VLOOKUP(ROWS($Z$2:$Z38),Table5[[#All],[Nub2]:[Location ]],2,0),"") | AG38: =OFFSET($AF$2,,,COUNTIF($AF$2:$AF$25,"?*")) -> #REF!
A39: {=ROW(38:38)} -> 38 | B39: I-0017 | C39: 900269 | D39: Cooking Oil 18LTR (ប្រេងឆា) | F39: CENTRAL KITCHEN | G39: FOOD | H39: Ingredients | I39: TIN | J39: TIN*18LTR | K39: 36 | L39: 36 | M39: 1 | N39: 10 | O39: =IF(ISNUMBER(SEARCH('Data Entry'!$J$3,$Q39)),MAX($O$1:$O38)+1,0) -> 0 | P39: =IF(ISNUMBER(SEARCH('Data Entry'!$J$3,$Q39)),MAX($P$1:$P38)+1,0) -> 0 | Q39: =Table2[[#This Row],[Item Name ]] -> Cooking Oil 18LTR (ប្រេងឆា) | R39: =IFERROR(VLOOKUP(ROWS($R$2:$R39),Table2[[Nub2]:[Name]],2,0),"") | W39: =IF(ISNUMBER(SEARCH('Data Entry'!$J$3,$Y39)),MAX($W$1:$W38)+1,0) -> 0 | X39: =IF(ISNUMBER(SEARCH('Data Entry'!$J$3,$Y39)),MAX($X$1:$X38)+1,0) -> 0 | Y39: Arome Khmer | Z39: =IFERROR(VLOOKUP(ROWS($Z$2:$Z39),Table4[[Nub2]:[Supplied Name]],2,0),"") | AA39: =OFFSET($Z$2,,,COUNTIF($Z$2:$Z$25,"?*")) -> #REF! | AC39: =IF(ISNUMBER(SEARCH('Data Entry'!$J$3,$AE39)),MAX($AC$1:$AC38)+1,0) -> 0 | AD39: =IF(ISNUMBER(SEARCH('Data Entry'!$J$3,$AE39)),MAX($AD$1:$AD38)+1,0) -> 0 | AF39: =IFERROR(VLOOKUP(ROWS($Z$2:$Z39),Table5[[#All],[Nub2]:[Location ]],2,0),"") | AG39: =OFFSET($AF$2,,,COUNTIF($AF$2:$AF$25,"?*")) -> #REF!
A40: {=ROW(39:39)} -> 39 | B40: I-0050 | C40: 900294 | D40: Roasted White Sesame Seed (ល្ងសលីង) | F40: CENTRAL KITCHEN | G40: FOOD | H40: Semi-Product | I40: KG | J40: KG | K40: 4.92 | M40: 1 | N40: 10 | O40: =IF(ISNUMBER(SEARCH('Data Entry'!$J$3,$Q40)),MAX($O$1:$O39)+1,0) -> 0 | P40: =IF(ISNUMBER(SEARCH('Data Entry'!$J$3,$Q40)),MAX($P$1:$P39)+1,0) -> 0 | Q40: =Table2[[#This Row],[Item Name ]] -> Roasted White Sesame Seed (ល្ងសលីង) | R40: =IFERROR(VLOOKUP(ROWS($R$2:$R40),Table2[[Nub2]:[Name]],2,0),"") | W40: =IF(ISNUMBER(SEARCH('Data Entry'!$J$3,$Y40)),MAX($W$1:$W39)+1,0) -> 0 | X40: =IF(ISNUMBER(SEARCH('Data Entry'!$J$3,$Y40)),MAX($X$1:$X39)+1,0) -> 0 | Y40: Asora Printing | Z40: =IFERROR(VLOOKUP(ROWS($Z$2:$Z40),Table4[[Nub2]:[Supplied Name]],2,0),"") | AA40: =OFFSET($Z$2,,,COUNTIF($Z$2:$Z$25,"?*")) -> #REF! | AC40: =IF(ISNUMBER(SEARCH('Data Entry'!$J$3,$AE40)),MAX($AC$1:$AC39)+1,0) -> 0 | AD40: =IF(ISNUMBER(SEARCH('Data Entry'!$J$3,$AE40)),MAX($AD$1:$AD39)+1,0) -> 0 | AF40: =IFERROR(VLOOKUP(ROWS($Z$2:$Z40),Table5[[#All],[Nub2]:[Location ]],2,0),"") | AG40: =OFFSET($AF$2,,,COUNTIF($AF$2:$AF$25,"?*")) -> #REF!
...

Sheet Data Entry
W1: Paid
W2: On Credit
G3: Search For | I3: Item Name | J3: Set Plastic Spoon & Fork (ឈុតស្លាបព្រា សម) | K3: =IFERROR(INDEX(Table2[Item Code],MATCH('Data Entry'!J3,Table2[[Item Name ]],0),0),"") -> P-0075 | P3: Invoice Value By Invoice | R3: =SUMIFS(Table49[TOTAL PRICE (USD)],Table49[Document Number],$Q$3) -> 0 | S3: TODAY | T3: Week 03
A4: Nº | B4: DATE | C4: Month | D4: Week Num2 | E4: PO Number | F4: Document Number | G4: Delivered From/To | H4: BARCODE | I4: ITEM CODE | J4: ITEM NAME | K4: PACKING SIZE | L4: PURCHASE Uom | M4: QUANTITY | N4: Master List Prices | O4: INV Prices | P4: PRICE (USD) | Q4: TOTAL PRICE (USD) | R4: LAST TOTAL PRICE (USD) | S4: EXPRIED DATE | T4: ALERT | U4: REMARK | V4: Transaction Type | W4: Category | X4: Sub Category | Y4: H1
A5: =IF(Table49[[#This Row],[ITEM NAME]]="","",ROW()-4) -> 1 | B5: 45901 | C5: =IFERROR(VLOOKUP(B5,Table14[],3,0),"") -> 9 | D5: =IFERROR(VLOOKUP(B5,Table14[],2,0),"") -> Week 01 | E5: PO30955 | F5: DN-010901 | G5: E-MART24 BKK1 | H5: =IFERROR(VLOOKUP(Table49[[#This Row],[ITEM CODE]],Table2[[Item Code]:[Master Name]],2,0),"") -> F0103010009 | I5: CSW-0001 | J5: =IFERROR(VLOOKUP(Table49[[#This Row],[ITEM CODE]],Table2[[Item Code]:[Master Name]],3,0),"") -> Tuna & Egg Sandwich | K5: =IFERROR(VLOOKUP(Table49[[#This Row],[ITEM CODE]],Table2[[Item Code]:[Master Name]],9,0),"") -> 1BOX*2PCS | L5: =IFERROR(VLOOKUP(Table49[[#This Row],[ITEM CODE]],Table2[[Item Code]:[Master Name]],8,0),"") -> BOX | M5: 2 | N5: =IFERROR(VLOOKUP(Table49[[#This Row],[ITEM CODE]],Table2[[#All],[Item Code]:[Unit Cost]],10,0),0) -> 1.5 | O5: =IFERROR(VLOOKUP(Table49[[#This Row],[ITEM CODE]],Table2[[#All],[Item Code]:[Unit Cost]],10,0),0) -> 1.5 | R5: =Table49[[#This Row],[QUANTITY]]*Table49[[#This Row],[INV Prices]] -> 3 | V5: Sold | W5: =IFERROR(VLOOKUP(Table49[[#This Row],[ITEM CODE]],Table2[[Item Code]:[Category ]],6,0),"") -> FOOD | X5: =IFERROR(VLOOKUP(Table49[[#This Row],[ITEM CODE]],Table2[[Item Code]:[Sub Category]],7,0),"") -> Sandwich | Y5: =Table49[[#This Row],[PO Number]]&COUNTIFS($E$5:E5,E5) -> PO309551
A6: =IF(Table49[[#This Row],[ITEM NAME]]="","",ROW()-4) -> 2 | B6: 45901 | C6: =IFERROR(VLOOKUP(B6,Table14[],3,0),"") -> 9 | D6: =IFERROR(VLOOKUP(B6,Table14[],2,0),"") -> Week 01 | E6: PO30955 | F6: DN-010901 | G6: E-MART24 BKK1 | H6: =IFERROR(VLOOKUP(Table49[[#This Row],[ITEM CODE]],Table2[[Item Code]:[Master Name]],2,0),"") -> F0103010010 | I6: CSW-0002 | J6: =IFERROR(VLOOKUP(Table49[[#This Row],[ITEM CODE]],Table2[[Item Code]:[Master Name]],3,0),"") -> Ham & Corn Sandwich | K6: =IFERROR(VLOOKUP(Table49[[#This Row],[ITEM CODE]],Table2[[Item Code]:[Master Name]],9,0),"") -> 1BOX*2PCS | L6: =IFERROR(VLOOKUP(Table49[[#This Row],[ITEM CODE]],Table2[[Item Code]:[Master Name]],8,0),"") -> BOX | M6: 2 | N6: =IFERROR(VLOOKUP(Table49[[#This Row],[ITEM CODE]],Table2[[#All],[Item Code]:[Unit Cost]],10,0),0) -> 1.5 | O6: =IFERROR(VLOOKUP(Table49[[#This Row],[ITEM CODE]],Table2[[#All],[Item Code]:[Unit Cost]],10,0),0) -> 1.5 | R6: =Table49[[#This Row],[QUANTITY]]*Table49[[#This Row],[INV Prices]] -> 3 | V6: Sold | W6: =IFERROR(VLOOKUP(Table49[[#This Row],[ITEM CODE]],Table2[[Item Code]:[Category ]],6,0),"") -> FOOD | X6: =IFERROR(VLOOKUP(Table49[[#This Row],[ITEM CODE]],Table2[[Item Code]:[Sub Category]],7,0),"") -> Sandwich | Y6: =Table49[[#This Row],[PO Number]]&COUNTIFS($E$5:E6,E6) -> PO309552
